Workbook

Sheet 目次
A1: 2027年度 売上・顧客情報管理
A2: 正式目標は「中立」：年 26,000,000円・649件。いちばん大事な先行指標は ④自社ネット新規（年143件）です。
A4: タブ | B4: 何のためのタブか | C4: いつ使うか
A5: 【まず見る】
A6: =HYPERLINK("#'目次'!A1","目次") | B6: このタブ。どこに何があるか | C6: 迷ったとき
A7: =HYPERLINK("#'ダッシュボード'!A1","ダッシュボード") | B7: 今月と累計の対計画、④自社ネット新規、提携先社数、赤字月の警告 | C7: 毎朝／毎週月曜
A8: 【毎日・毎月の入力】
A9: =HYPERLINK("#'1月_売上顧客'!A1","1月_売上顧客 〜 12月_売上顧客") | B9: 1件1行で施工を記録。2行目に今月の目標、4行目に自動集計 | C9: 施工したその日
A10: =HYPERLINK("#'1月_支出成績'!A1","1月_支出成績 〜 12月_支出成績") | B10: 左が経費入力、右（M列）が月次P/L。P/Lは行が動きません | C10: 経費が出たとき／月末
A11: 【計画と実績】
A12: =HYPERLINK("#'2027年計画'!A1","2027年計画") | B12: 中立（正式目標）の月次と、保守・攻めの年計。実績で書き換えない | C12: 年初・四半期の判定ゲート
A13: =HYPERLINK("#'年間成績'!A1","年間成績") | B13: 予算対実績・月別P/L・対計画の差額。2026年売上の行だけ手入力 | C13: 毎月1日
A14: 【2027年の新しい取り組み】
A15: =HYPERLINK("#'ネット流入_週次'!A1","ネット流入_週次") | B15: SNS・ブログ・GBP・予約フォーム・受注・広告費・CPA。CPA9,500円超は赤 | C15: 毎週金曜
A16: =HYPERLINK("#'広告_段管理'!A1","広告_段管理") | B16: 段0→段3。月ごとに予算・実績・CPA・次の段へ上がるかの判定 | C16: 月末
A17: =HYPERLINK("#'提携先_パイプライン'!A1","提携先_パイプライン") | B17: アクティブ10社→15社。最終接触日・接触回数・ステージ・次アクション | C17: 接触のたび
A18: =HYPERLINK("#'協力業者_管理'!A1","協力業者_管理") | B18: 3社。契約条件・回した件数・支払額・品質（クレーム・写真提出） | C18: 月末
A19: =HYPERLINK("#'Web予約受信'!A1","Web予約受信") | B19: 予約フォーム／LPからの受信ログ。流入元(?src=)と台帳への転記チェック | C19: 受信したその日
A20: 【顧客と再販】
A21: =HYPERLINK("#'顧客管理台帳'!A1","顧客管理台帳") | B21: ヘッダー15行目・データ16行目から。2027年版は空の器（移行は年末） | C21: 施工の記録後
A22: =HYPERLINK("#'再販リスト'!A1","再販リスト") | B22: メニュー別サイクルで案内時期が来た方を抽出する器 | C22: 再販の波を出す前
A23: =HYPERLINK("#'分析_件数単価流入'!A1","分析_件数単価流入") | B23: 月別の件数・単価と流入経路別の内訳。すべて自動 | C23: 見たいとき
A24: =HYPERLINK("#'分析_流入経路とLTV'!A1","分析_流入経路とLTV") | B24: 入口ごとのLTVとリピート率。広告CPA上限9,500円の根拠 | C24: 広告の判断のとき
A25: 【運用】
A26: =HYPERLINK("#'見積ルール'!A1","見積ルール") | B26: 料金表（税込）と割引・紹介のルール。正データは data/prices.json | C26: 見積のとき
A27: =HYPERLINK("#'TODO'!A1","TODO") | B27: 状態・期限・優先度。完了しても行を消さない | C27: 随時
A28: =HYPERLINK("#'勤怠管理'!A1","勤怠管理") | B28: 日付・氏名・時間・現場数。現場人件費（原価）の根拠 | C28: 毎日
A29: =HYPERLINK("#'メモ・変更履歴'!A1","メモ・変更履歴") | B29: このスプレッドシートに手を入れた記録 | C29: 手を入れたとき
A30: =HYPERLINK("#'選択肢マスター'!A1","選択肢マスター") | B30: 全タブのプルダウンの元データ。並べ替え・行削除をしないこと | C30: 選択肢を足すとき
A32: 【この表は必ず最新にすること】
A33: タブを足したり名前を変えたら、この目次も直してください（2026年版は目次が古くて実在タブが載っていませんでした）。
A35: 【2027年の決まり】
A36: ・料金は data/prices.json が正（税込）。繁忙期加算 3,300円は5・6・7・12月
A37: ・満足度は 98.6%（209名中206名）。「98.8%」は使わない
A38: ・対応エリアは東京都・千葉県・神奈川県
A39: ・お客様に届くもの（SMS・LINE・メール・電話台本）は、台帳の最新の施工の名義と機械照合してから作る
A40: ・お客様が開くページは tools/check-public-page.py を通してから配信する
A42: シート数：42タブ ／ 生成：tools/build-sheet-2027.py

Sheet ダッシュボード
A1: ダッシュボード — 計画に乗っているか、1画面で
A2: B3 に「今月の数字（1〜12）」を入れると、その月の数字に切り替わります。
A3: 今月（1〜12を入れる） | B3: 1 | C3: ← ここだけ手で変えます
A5: ▼ 今月 | B5: 計画 | C5: 実績 | D5: 差額
A6: 売上 | B6: =INDEX('年間成績'!$B$18:$M$18,1,$B$3) | C6: =INDEX('年間成績'!$B$20:$M$20,1,$B$3) | D6: =C6-B6
A7: 件数 | B7: =INDEX('年間成績'!$B$27:$M$27,1,$B$3) | C7: =INDEX('年間成績'!$B$28:$M$28,1,$B$3) | D7: =C7-B7
A8: ★④自社ネット新規 | B8: =INDEX('年間成績'!$B$29:$M$29,1,$B$3) | C8: =INDEX('年間成績'!$B$30:$M$30,1,$B$3) | D8: =C8-B8
A9: 達成率（当月） | C9: =IFERROR(C6/B6,0)
A10: 経常利益（当月） | B10: =INDEX('年間成績'!$B$51:$M$51,1,$B$3) | C10: =INDEX('年間成績'!$B$43:$M$43,1,$B$3) | D10: =C10-B10
A12: ▼ 年間累計 | B12: 計画 | C12: 実績 | D12: 差額
A13: 売上 累計 | B13: =INDEX('年間成績'!$B$22:$M$22,1,$B$3) | C13: =INDEX('年間成績'!$B$21:$M$21,1,$B$3) | D13: =C13-B13 | E13: ※ 「今月」までの累計どうしで比べています。年計画は 売上26,000,000円・④143件・経常利益5,851,371円（中立）
A14: ★④自社ネット新規 累計 | B14: =INDEX('年間成績'!$B$49:$M$49,1,$B$3) | C14: =INDEX('年間成績'!$B$50:$M$50,1,$B$3) | D14: =C14-B14
A15: 経常利益 累計 | B15: =INDEX('年間成績'!$B$52:$M$52,1,$B$3) | C15: =INDEX('年間成績'!$B$44:$M$44,1,$B$3) | D15: =C15-B15
A17: ▼ ★④自社ネット新規（2027年の最重要KPI）
A18: 月 | B18: 1月 | C18: 2月 | D18: 3月 | E18: 4月 | F18: 5月 | G18: 6月 | H18: 7月 | I18: 8月 | J18: 9月 | K18: 10月 | L18: 11月 | M18: 12月 | N18: 年計
A19: 目標 | B19: ='年間成績'!B29 | C19: ='年間成績'!C29 | D19: ='年間成績'!D29 | E19: ='年間成績'!E29 | F19: ='年間成績'!F29 | G19: ='年間成績'!G29 | H19: ='年間成績'!H29 | I19: ='年間成績'!I29 | ... M19: ='年間成績'!M29 | N19: =SUM(B19:M19)
A20: 実績 | B20: ='年間成績'!B30 | C20: ='年間成績'!C30 | D20: ='年間成績'!D30 | E20: ='年間成績'!E30 | F20: ='年間成績'!F30 | G20: ='年間成績'!G30 | H20: ='年間成績'!H30 | I20: ='年間成績'!I30 | ... M20: ='年間成績'!M30 | N20: =SUM(B20:M20)
A21: 差 | B21: =B20-B19 | C21: =C20-C19 | D21: =D20-D19 | E21: =E20-E19 | F21: =F20-F19 | G21: =G20-G19 | H21: =H20-H19 | I21: =I20-I19 | ... N21: =N20-N19
A23: ▼ 先行指標と警告 | B23: 現在 | C23: 目標/上限 | D23: 意味
A24: 提携先 新規の成約 社数 | B24: =COUNTIF('提携先_パイプライン'!$G$5:$G$104,"成約") | C24: 5 | D24: アクティブ10社→15社。1社増えると年50万円規模で効く
A25: 協力業者 契約社数 | B25: =COUNTA('協力業者_管理'!$A$5:$A$24)-COUNTIF('協力業者_管理'!$B$5:$B$24,"未契約") | C25: 3 | D25: 1〜2月に契約、3月から稼働
A26: 経常利益がマイナスの月数 | B26: ='年間成績'!$B$14 | C26: 0 | D26: ★赤字月。0であること
A27: CPAが9,500円を超えた月数 | B27: =COUNTIF('広告_段管理'!$F$5:$F$16,">9500") | C27: 0 | D27: ★超えた月はその月で広告を止める
A28: Web予約 未対応の件数 | B28: =COUNTIF('Web予約受信'!$B$5:$B$504,"未対応") | C28: 0 | D28: ★放置ゼロ。当日中に連絡
A29: 自社（One Hitter）売上 累計 | B29: ='年間成績'!$N$56 | D29: 本舗の1円はロイヤリティで39銭出ていく。自社の1円のほうが残る
A30: 【毎月これだけ見れば足ります】① ④自社ネット新規の件数 ② 提携先の社数 ③ 累計の対計画の差額
A31: ④が動かなければ、他は全部後追いにしかなりません（docs/2027-数値目標.md §8）。

Sheet 1月_売上顧客
A1: ◆ 1月の売上・顧客。入力は 5 行目から。2行目＝今月の目標、4行目＝自動集計（数式・触らない）
A2: 今月目標(売上) | B2: 1440000 | C2: 売上 現在 | D2: =$L$4 | E2: 過不足 | F2: =D2-B2 | G2: 達成率 | H2: =IFERROR(D2/B2,0) | I2: 必要件数 | J2: 37 | K2: 件数 現在 | L2: =$E$4 | M2: 残り件数 | N2: =J2-L2 | O2: ④ネット新規 目標 | P2: 5 | Q2: ④ 現在 | R2: =$R$4
A3: 通し番号 | B3: 売上種類 | C3: 受注日 | D3: 施工日付 | E3: 流入経路 | F3: 流入元の識別子(?src=) | G3: 紹介者（顧客ID） | H3: 氏名 | I3: TEL(-無し) | J3: 郵便番号(-無し) | K3: 住所 | L3: 売上（税込） | M3: 実施メニュー | N3: 施工担当 | O3: フォローコール日 | P3: 早期予約提案 | Q3: フォローコール | R3: 備考(お客様の声) | S3: 入金経路 | T3: 入金額照合 | U3: ＯＨ打診 | V3: 本舗ロイ区分 | W3: お客様周辺/環境情報 | X3: カウント用
A4: ="▼自動集計" | B4: =COUNTIFS($B$5:$B$504,"One Hitter") | C4: =IFERROR(SUMPRODUCT(($C$5:$C$504<>"")*($D$5:$D$504<>"")*($D$5:$D$504-$C$5:$C$504))/SUMPRODUCT(($C$5:$C$504<>"")*($D$5:$D$504<>"")),0) | D4: =COUNTIFS($B$5:$B$504,"本舗") | E4: =COUNTA($D$5:$D$504) | F4: =IFERROR(SUM($L$5:$L$504)/COUNTA($D$5:$D$504),0) | G4: =COUNTA($G$5:$G$504) | H4: =IFERROR(SUMIFS($L$5:$L$504,$B$5:$B$504,"One Hitter")/COUNTIFS($B$5:$B$504,"One Hitter"),0) | I4: =IFERROR(SUMIFS($L$5:$L$504,$B$5:$B$504,"本舗")/COUNTIFS($B$5:$B$504,"本舗"),0) | J4: =SUMIFS($L$5:$L$504,$B$5:$B$504,"One Hitter") | K4: =SUMIFS($L$5:$L$504,$B$5:$B$504,"本舗") | L4: =SUM($L$5:$L$504) | R4: =COUNTIFS($E$5:$E$504,"HP")+COUNTIFS($E$5:$E$504,"LP")+COUNTIFS($E$5:$E$504,"SNS")+COUNTIFS($E$5:$E$504,"GBP(地図検索)")+COUNTIFS($E$5:$E$504,"公式LINE")+COUNTIFS($E$5:$E$504,"アフィリエイト")+COUNTIFS($E$5:$E$504,"LINE/SMS再販")+COUNTIFS($E$5:$E$504,"SMS")+COUNTIFS($E$5:$E$504,"広告") | S4: =SUMIFS($L$5:$L$504,$E$5:$E$504,"HP")+SUMIFS($L$5:$L$504,$E$5:$E$504,"LP")+SUMIFS($L$5:$L$504,$E$5:$E$504,"SNS")+SUMIFS($L$5:$L$504,$E$5:$E$504,"GBP(地図検索)")+SUMIFS($L$5:$L$504,$E$5:$E$504,"公式LINE")+SUMIFS($L$5:$L$504,$E$5:$E$504,"アフィリエイト")+SUMIFS($L$5:$L$504,$E$5:$E$504,"LINE/SMS再販")+SUMIFS($L$5:$L$504,$E$5:$E$504,"SMS")+SUMIFS($L$5:$L$504,$E$5:$E$504,"広告")

Sheet 2月_売上顧客
A1: ◆ 2月の売上・顧客。入力は 5 行目から。2行目＝今月の目標、4行目＝自動集計（数式・触らない）
A2: 今月目標(売上) | B2: 1280000 | C2: 売上 現在 | D2: =$L$4 | E2: 過不足 | F2: =D2-B2 | G2: 達成率 | H2: =IFERROR(D2/B2,0) | I2: 必要件数 | J2: 32 | K2: 件数 現在 | L2: =$E$4 | M2: 残り件数 | N2: =J2-L2 | O2: ④ネット新規 目標 | P2: 5 | Q2: ④ 現在 | R2: =$R$4
A3: 通し番号 | B3: 売上種類 | C3: 受注日 | D3: 施工日付 | E3: 流入経路 | F3: 流入元の識別子(?src=) | G3: 紹介者（顧客ID） | H3: 氏名 | I3: TEL(-無し) | J3: 郵便番号(-無し) | K3: 住所 | L3: 売上（税込） | M3: 実施メニュー | N3: 施工担当 | O3: フォローコール日 | P3: 早期予約提案 | Q3: フォローコール | R3: 備考(お客様の声) | S3: 入金経路 | T3: 入金額照合 | U3: ＯＨ打診 | V3: 本舗ロイ区分 | W3: お客様周辺/環境情報 | X3: カウント用
A4: ="▼自動集計" | B4: =COUNTIFS($B$5:$B$504,"One Hitter") | C4: =IFERROR(SUMPRODUCT(($C$5:$C$504<>"")*($D$5:$D$504<>"")*($D$5:$D$504-$C$5:$C$504))/SUMPRODUCT(($C$5:$C$504<>"")*($D$5:$D$504<>"")),0) | D4: =COUNTIFS($B$5:$B$504,"本舗") | E4: =COUNTA($D$5:$D$504) | F4: =IFERROR(SUM($L$5:$L$504)/COUNTA($D$5:$D$504),0) | G4: =COUNTA($G$5:$G$504) | H4: =IFERROR(SUMIFS($L$5:$L$504,$B$5:$B$504,"One Hitter")/COUNTIFS($B$5:$B$504,"One Hitter"),0) | I4: =IFERROR(SUMIFS($L$5:$L$504,$B$5:$B$504,"本舗")/COUNTIFS($B$5:$B$504,"本舗"),0) | J4: =SUMIFS($L$5:$L$504,$B$5:$B$504,"One Hitter") | K4: =SUMIFS($L$5:$L$504,$B$5:$B$504,"本舗") | L4: =SUM($L$5:$L$504) | R4: =COUNTIFS($E$5:$E$504,"HP")+COUNTIFS($E$5:$E$504,"LP")+COUNTIFS($E$5:$E$504,"SNS")+COUNTIFS($E$5:$E$504,"GBP(地図検索)")+COUNTIFS($E$5:$E$504,"公式LINE")+COUNTIFS($E$5:$E$504,"アフィリエイト")+COUNTIFS($E$5:$E$504,"LINE/SMS再販")+COUNTIFS($E$5:$E$504,"SMS")+COUNTIFS($E$5:$E$504,"広告") | S4: =SUMIFS($L$5:$L$504,$E$5:$E$504,"HP")+SUMIFS($L$5:$L$504,$E$5:$E$504,"LP")+SUMIFS($L$5:$L$504,$E$5:$E$504,"SNS")+SUMIFS($L$5:$L$504,$E$5:$E$504,"GBP(地図検索)")+SUMIFS($L$5:$L$504,$E$5:$E$504,"公式LINE")+SUMIFS($L$5:$L$504,$E$5:$E$504,"アフィリエイト")+SUMIFS($L$5:$L$504,$E$5:$E$504,"LINE/SMS再販")+SUMIFS($L$5:$L$504,$E$5:$E$504,"SMS")+SUMIFS($L$5:$L$504,$E$5:$E$504,"広告")

Sheet 3月_売上顧客
A1: ◆ 3月の売上・顧客。入力は 5 行目から。2行目＝今月の目標、4行目＝自動集計（数式・触らない）
A2: 今月目標(売上) | B2: 1850000 | C2: 売上 現在 | D2: =$L$4 | E2: 過不足 | F2: =D2-B2 | G2: 達成率 | H2: =IFERROR(D2/B2,0) | I2: 必要件数 | J2: 46 | K2: 件数 現在 | L2: =$E$4 | M2: 残り件数 | N2: =J2-L2 | O2: ④ネット新規 目標 | P2: 8 | Q2: ④ 現在 | R2: =$R$4
A3: 通し番号 | B3: 売上種類 | C3: 受注日 | D3: 施工日付 | E3: 流入経路 | F3: 流入元の識別子(?src=) | G3: 紹介者（顧客ID） | H3: 氏名 | I3: TEL(-無し) | J3: 郵便番号(-無し) | K3: 住所 | L3: 売上（税込） | M3: 実施メニュー | N3: 施工担当 | O3: フォローコール日 | P3: 早期予約提案 | Q3: フォローコール | R3: 備考(お客様の声) | S3: 入金経路 | T3: 入金額照合 | U3: ＯＨ打診 | V3: 本舗ロイ区分 | W3: お客様周辺/環境情報 | X3: カウント用
A4: ="▼自動集計" | B4: =COUNTIFS($B$5:$B$504,"One Hitter") | C4: =IFERROR(SUMPRODUCT(($C$5:$C$504<>"")*($D$5:$D$504<>"")*($D$5:$D$504-$C$5:$C$504))/SUMPRODUCT(($C$5:$C$504<>"")*($D$5:$D$504<>"")),0) | D4: =COUNTIFS($B$5:$B$504,"本舗") | E4: =COUNTA($D$5:$D$504) | F4: =IFERROR(SUM($L$5:$L$504)/COUNTA($D$5:$D$504),0) | G4: =COUNTA($G$5:$G$504) | H4: =IFERROR(SUMIFS($L$5:$L$504,$B$5:$B$504,"One Hitter")/COUNTIFS($B$5:$B$504,"One Hitter"),0) | I4: =IFERROR(SUMIFS($L$5:$L$504,$B$5:$B$504,"本舗")/COUNTIFS($B$5:$B$504,"本舗"),0) | J4: =SUMIFS($L$5:$L$504,$B$5:$B$504,"One Hitter") | K4: =SUMIFS($L$5:$L$504,$B$5:$B$504,"本舗") | L4: =SUM($L$5:$L$504) | R4: =COUNTIFS($E$5:$E$504,"HP")+COUNTIFS($E$5:$E$504,"LP")+COUNTIFS($E$5:$E$504,"SNS")+COUNTIFS($E$5:$E$504,"GBP(地図検索)")+COUNTIFS($E$5:$E$504,"公式LINE")+COUNTIFS($E$5:$E$504,"アフィリエイト")+COUNTIFS($E$5:$E$504,"LINE/SMS再販")+COUNTIFS($E$5:$E$504,"SMS")+COUNTIFS($E$5:$E$504,"広告") | S4: =SUMIFS($L$5:$L$504,$E$5:$E$504,"HP")+SUMIFS($L$5:$L$504,$E$5:$E$504,"LP")+SUMIFS($L$5:$L$504,$E$5:$E$504,"SNS")+SUMIFS($L$5:$L$504,$E$5:$E$504,"GBP(地図検索)")+SUMIFS($L$5:$L$504,$E$5:$E$504,"公式LINE")+SUMIFS($L$5:$L$504,$E$5:$E$504,"アフィリエイト")+SUMIFS($L$5:$L$504,$E$5:$E$504,"LINE/SMS再販")+SUMIFS($L$5:$L$504,$E$5:$E$504,"SMS")+SUMIFS($L$5:$L$504,$E$5:$E$504,"広告")

Sheet 4月_売上顧客
A1: ◆ 4月の売上・顧客。入力は 5 行目から。2行目＝今月の目標、4行目＝自動集計（数式・触らない）
A2: 今月目標(売上) | B2: 2260000 | C2: 売上 現在 | D2: =$L$4 | E2: 過不足 | F2: =D2-B2 | G2: 達成率 | H2: =IFERROR(D2/B2,0) | I2: 必要件数 | J2: 57 | K2: 件数 現在 | L2: =$E$4 | M2: 残り件数 | N2: =J2-L2 | O2: ④ネット新規 目標 | P2: 10 | Q2: ④ 現在 | R2: =$R$4
A3: 通し番号 | B3: 売上種類 | C3: 受注日 | D3: 施工日付 | E3: 流入経路 | F3: 流入元の識別子(?src=) | G3: 紹介者（顧客ID） | H3: 氏名 | I3: TEL(-無し) | J3: 郵便番号(-無し) | K3: 住所 | L3: 売上（税込） | M3: 実施メニュー | N3: 施工担当 | O3: フォローコール日 | P3: 早期予約提案 | Q3: フォローコール | R3: 備考(お客様の声) | S3: 入金経路 | T3: 入金額照合 | U3: ＯＨ打診 | V3: 本舗ロイ区分 | W3: お客様周辺/環境情報 | X3: カウント用
A4: ="▼自動集計" | B4: =COUNTIFS($B$5:$B$504,"One Hitter") | C4: =IFERROR(SUMPRODUCT(($C$5:$C$504<>"")*($D$5:$D$504<>"")*($D$5:$D$504-$C$5:$C$504))/SUMPRODUCT(($C$5:$C$504<>"")*($D$5:$D$504<>"")),0) | D4: =COUNTIFS($B$5:$B$504,"本舗") | E4: =COUNTA($D$5:$D$504) | F4: =IFERROR(SUM($L$5:$L$504)/COUNTA($D$5:$D$504),0) | G4: =COUNTA($G$5:$G$504) | H4: =IFERROR(SUMIFS($L$5:$L$504,$B$5:$B$504,"One Hitter")/COUNTIFS($B$5:$B$504,"One Hitter"),0) | I4: =IFERROR(SUMIFS($L$5:$L$504,$B$5:$B$504,"本舗")/COUNTIFS($B$5:$B$504,"本舗"),0) | J4: =SUMIFS($L$5:$L$504,$B$5:$B$504,"One Hitter") | K4: =SUMIFS($L$5:$L$504,$B$5:$B$504,"本舗") | L4: =SUM($L$5:$L$504) | R4: =COUNTIFS($E$5:$E$504,"HP")+COUNTIFS($E$5:$E$504,"LP")+COUNTIFS($E$5:$E$504,"SNS")+COUNTIFS($E$5:$E$504,"GBP(地図検索)")+COUNTIFS($E$5:$E$504,"公式LINE")+COUNTIFS($E$5:$E$504,"アフィリエイト")+COUNTIFS($E$5:$E$504,"LINE/SMS再販")+COUNTIFS($E$5:$E$504,"SMS")+COUNTIFS($E$5:$E$504,"広告") | S4: =SUMIFS($L$5:$L$504,$E$5:$E$504,"HP")+SUMIFS($L$5:$L$504,$E$5:$E$504,"LP")+SUMIFS($L$5:$L$504,$E$5:$E$504,"SNS")+SUMIFS($L$5:$L$504,$E$5:$E$504,"GBP(地図検索)")+SUMIFS($L$5:$L$504,$E$5:$E$504,"公式LINE")+SUMIFS($L$5:$L$504,$E$5:$E$504,"アフィリエイト")+SUMIFS($L$5:$L$504,$E$5:$E$504,"LINE/SMS再販")+SUMIFS($L$5:$L$504,$E$5:$E$504,"SMS")+SUMIFS($L$5:$L$504,$E$5:$E$504,"広告")

Sheet 5月_売上顧客
A1: ◆ 5月の売上・顧客。入力は 5 行目から。2行目＝今月の目標、4行目＝自動集計（数式・触らない）
A2: 今月目標(売上) | B2: 2890000 | C2: 売上 現在 | D2: =$L$4 | E2: 過不足 | F2: =D2-B2 | G2: 達成率 | H2: =IFERROR(D2/B2,0) | I2: 必要件数 | J2: 70 | K2: 件数 現在 | L2: =$E$4 | M2: 残り件数 | N2: =J2-L2 | O2: ④ネット新規 目標 | P2: 14 | Q2: ④ 現在 | R2: =$R$4
A3: 通し番号 | B3: 売上種類 | C3: 受注日 | D3: 施工日付 | E3: 流入経路 | F3: 流入元の識別子(?src=) | G3: 紹介者（顧客ID） | H3: 氏名 | I3: TEL(-無し) | J3: 郵便番号(-無し) | K3: 住所 | L3: 売上（税込） | M3: 実施メニュー | N3: 施工担当 | O3: フォローコール日 | P3: 早期予約提案 | Q3: フォローコール | R3: 備考(お客様の声) | S3: 入金経路 | T3: 入金額照合 | U3: ＯＨ打診 | V3: 本舗ロイ区分 | W3: お客様周辺/環境情報 | X3: カウント用
A4: ="▼自動集計" | B4: =COUNTIFS($B$5:$B$504,"One Hitter") | C4: =IFERROR(SUMPRODUCT(($C$5:$C$504<>"")*($D$5:$D$504<>"")*($D$5:$D$504-$C$5:$C$504))/SUMPRODUCT(($C$5:$C$504<>"")*($D$5:$D$504<>"")),0) | D4: =COUNTIFS($B$5:$B$504,"本舗") | E4: =COUNTA($D$5:$D$504) | F4: =IFERROR(SUM($L$5:$L$504)/COUNTA($D$5:$D$504),0) | G4: =COUNTA($G$5:$G$504) | H4: =IFERROR(SUMIFS($L$5:$L$504,$B$5:$B$504,"One Hitter")/COUNTIFS($B$5:$B$504,"One Hitter"),0) | I4: =IFERROR(SUMIFS($L$5:$L$504,$B$5:$B$504,"本舗")/COUNTIFS($B$5:$B$504,"本舗"),0) | J4: =SUMIFS($L$5:$L$504,$B$5:$B$504,"One Hitter") | K4: =SUMIFS($L$5:$L$504,$B$5:$B$504,"本舗") | L4: =SUM($L$5:$L$504) | R4: =COUNTIFS($E$5:$E$504,"HP")+COUNTIFS($E$5:$E$504,"LP")+COUNTIFS($E$5:$E$504,"SNS")+COUNTIFS($E$5:$E$504,"GBP(地図検索)")+COUNTIFS($E$5:$E$504,"公式LINE")+COUNTIFS($E$5:$E$504,"アフィリエイト")+COUNTIFS($E$5:$E$504,"LINE/SMS再販")+COUNTIFS($E$5:$E$504,"SMS")+COUNTIFS($E$5:$E$504,"広告") | S4: =SUMIFS($L$5:$L$504,$E$5:$E$504,"HP")+SUMIFS($L$5:$L$504,$E$5:$E$504,"LP")+SUMIFS($L$5:$L$504,$E$5:$E$504,"SNS")+SUMIFS($L$5:$L$504,$E$5:$E$504,"GBP(地図検索)")+SUMIFS($L$5:$L$504,$E$5:$E$504,"公式LINE")+SUMIFS($L$5:$L$504,$E$5:$E$504,"アフィリエイト")+SUMIFS($L$5:$L$504,$E$5:$E$504,"LINE/SMS再販")+SUMIFS($L$5:$L$504,$E$5:$E$504,"SMS")+SUMIFS($L$5:$L$504,$E$5:$E$504,"広告")

Sheet 6月_売上顧客
A1: ◆ 6月の売上・顧客。入力は 5 行目から。2行目＝今月の目標、4行目＝自動集計（数式・触らない）
A2: 今月目標(売上) | B2: 3400000 | C2: 売上 現在 | D2: =$L$4 | E2: 過不足 | F2: =D2-B2 | G2: 達成率 | H2: =IFERROR(D2/B2,0) | I2: 必要件数 | J2: 82 | K2: 件数 現在 | L2: =$E$4 | M2: 残り件数 | N2: =J2-L2 | O2: ④ネット新規 目標 | P2: 17 | Q2: ④ 現在 | R2: =$R$4
A3: 通し番号 | B3: 売上種類 | C3: 受注日 | D3: 施工日付 | E3: 流入経路 | F3: 流入元の識別子(?src=) | G3: 紹介者（顧客ID） | H3: 氏名 | I3: TEL(-無し) | J3: 郵便番号(-無し) | K3: 住所 | L3: 売上（税込） | M3: 実施メニュー | N3: 施工担当 | O3: フォローコール日 | P3: 早期予約提案 | Q3: フォローコール | R3: 備考(お客様の声) | S3: 入金経路 | T3: 入金額照合 | U3: ＯＨ打診 | V3: 本舗ロイ区分 | W3: お客様周辺/環境情報 | X3: カウント用
A4: ="▼自動集計" | B4: =COUNTIFS($B$5:$B$504,"One Hitter") | C4: =IFERROR(SUMPRODUCT(($C$5:$C$504<>"")*($D$5:$D$504<>"")*($D$5:$D$504-$C$5:$C$504))/SUMPRODUCT(($C$5:$C$504<>"")*($D$5:$D$504<>"")),0) | D4: =COUNTIFS($B$5:$B$504,"本舗") | E4: =COUNTA($D$5:$D$504) | F4: =IFERROR(SUM($L$5:$L$504)/COUNTA($D$5:$D$504),0) | G4: =COUNTA($G$5:$G$504) | H4: =IFERROR(SUMIFS($L$5:$L$504,$B$5:$B$504,"One Hitter")/COUNTIFS($B$5:$B$504,"One Hitter"),0) | I4: =IFERROR(SUMIFS($L$5:$L$504,$B$5:$B$504,"本舗")/COUNTIFS($B$5:$B$504,"本舗"),0) | J4: =SUMIFS($L$5:$L$504,$B$5:$B$504,"One Hitter") | K4: =SUMIFS($L$5:$L$504,$B$5:$B$504,"本舗") | L4: =SUM($L$5:$L$504) | R4: =COUNTIFS($E$5:$E$504,"HP")+COUNTIFS($E$5:$E$504,"LP")+COUNTIFS($E$5:$E$504,"SNS")+COUNTIFS($E$5:$E$504,"GBP(地図検索)")+COUNTIFS($E$5:$E$504,"公式LINE")+COUNTIFS($E$5:$E$504,"アフィリエイト")+COUNTIFS($E$5:$E$504,"LINE/SMS再販")+COUNTIFS($E$5:$E$504,"SMS")+COUNTIFS($E$5:$E$504,"広告") | S4: =SUMIFS($L$5:$L$504,$E$5:$E$504,"HP")+SUMIFS($L$5:$L$504,$E$5:$E$504,"LP")+SUMIFS($L$5:$L$504,$E$5:$E$504,"SNS")+SUMIFS($L$5:$L$504,$E$5:$E$504,"GBP(地図検索)")+SUMIFS($L$5:$L$504,$E$5:$E$504,"公式LINE")+SUMIFS($L$5:$L$504,$E$5:$E$504,"アフィリエイト")+SUMIFS($L$5:$L$504,$E$5:$E$504,"LINE/SMS再販")+SUMIFS($L$5:$L$504,$E$5:$E$504,"SMS")+SUMIFS($L$5:$L$504,$E$5:$E$504,"広告")

Sheet 7月_売上顧客
A1: ◆ 7月の売上・顧客。入力は 5 行目から。2行目＝今月の目標、4行目＝自動集計（数式・触らない）
A2: 今月目標(売上) | B2: 2740000 | C2: 売上 現在 | D2: =$L$4 | E2: 過不足 | F2: =D2-B2 | G2: 達成率 | H2: =IFERROR(D2/B2,0) | I2: 必要件数 | J2: 68 | K2: 件数 現在 | L2: =$E$4 | M2: 残り件数 | N2: =J2-L2 | O2: ④ネット新規 目標 | P2: 15 | Q2: ④ 現在 | R2: =$R$4
A3: 通し番号 | B3: 売上種類 | C3: 受注日 | D3: 施工日付 | E3: 流入経路 | F3: 流入元の識別子(?src=) | G3: 紹介者（顧客ID） | H3: 氏名 | I3: TEL(-無し) | J3: 郵便番号(-無し) | K3: 住所 | L3: 売上（税込） | M3: 実施メニュー | N3: 施工担当 | O3: フォローコール日 | P3: 早期予約提案 | Q3: フォローコール | R3: 備考(お客様の声) | S3: 入金経路 | T3: 入金額照合 | U3: ＯＨ打診 | V3: 本舗ロイ区分 | W3: お客様周辺/環境情報 | X3: カウント用
A4: ="▼自動集計" | B4: =COUNTIFS($B$5:$B$504,"One Hitter") | C4: =IFERROR(SUMPRODUCT(($C$5:$C$504<>"")*($D$5:$D$504<>"")*($D$5:$D$504-$C$5:$C$504))/SUMPRODUCT(($C$5:$C$504<>"")*($D$5:$D$504<>"")),0) | D4: =COUNTIFS($B$5:$B$504,"本舗") | E4: =COUNTA($D$5:$D$504) | F4: =IFERROR(SUM($L$5:$L$504)/COUNTA($D$5:$D$504),0) | G4: =COUNTA($G$5:$G$504) | H4: =IFERROR(SUMIFS($L$5:$L$504,$B$5:$B$504,"One Hitter")/COUNTIFS($B$5:$B$504,"One Hitter"),0) | I4: =IFERROR(SUMIFS($L$5:$L$504,$B$5:$B$504,"本舗")/COUNTIFS($B$5:$B$504,"本舗"),0) | J4: =SUMIFS($L$5:$L$504,$B$5:$B$504,"One Hitter") | K4: =SUMIFS($L$5:$L$504,$B$5:$B$504,"本舗") | L4: =SUM($L$5:$L$504) | R4: =COUNTIFS($E$5:$E$504,"HP")+COUNTIFS($E$5:$E$504,"LP")+COUNTIFS($E$5:$E$504,"SNS")+COUNTIFS($E$5:$E$504,"GBP(地図検索)")+COUNTIFS($E$5:$E$504,"公式LINE")+COUNTIFS($E$5:$E$504,"アフィリエイト")+COUNTIFS($E$5:$E$504,"LINE/SMS再販")+COUNTIFS($E$5:$E$504,"SMS")+COUNTIFS($E$5:$E$504,"広告") | S4: =SUMIFS($L$5:$L$504,$E$5:$E$504,"HP")+SUMIFS($L$5:$L$504,$E$5:$E$504,"LP")+SUMIFS($L$5:$L$504,$E$5:$E$504,"SNS")+SUMIFS($L$5:$L$504,$E$5:$E$504,"GBP(地図検索)")+SUMIFS($L$5:$L$504,$E$5:$E$504,"公式LINE")+SUMIFS($L$5:$L$504,$E$5:$E$504,"アフィリエイト")+SUMIFS($L$5:$L$504,$E$5:$E$504,"LINE/SMS再販")+SUMIFS($L$5:$L$504,$E$5:$E$504,"SMS")+SUMIFS($L$5:$L$504,$E$5:$E$504,"広告")

Sheet 8月_売上顧客
A1: ◆ 8月の売上・顧客。入力は 5 行目から。2行目＝今月の目標、4行目＝自動集計（数式・触らない）
A2: 今月目標(売上) | B2: 1600000 | C2: 売上 現在 | D2: =$L$4 | E2: 過不足 | F2: =D2-B2 | G2: 達成率 | H2: =IFERROR(D2/B2,0) | I2: 必要件数 | J2: 42 | K2: 件数 現在 | L2: =$E$4 | M2: 残り件数 | N2: =J2-L2 | O2: ④ネット新規 目標 | P2: 10 | Q2: ④ 現在 | R2: =$R$4
A3: 通し番号 | B3: 売上種類 | C3: 受注日 | D3: 施工日付 | E3: 流入経路 | F3: 流入元の識別子(?src=) | G3: 紹介者（顧客ID） | H3: 氏名 | I3: TEL(-無し) | J3: 郵便番号(-無し) | K3: 住所 | L3: 売上（税込） | M3: 実施メニュー | N3: 施工担当 | O3: フォローコール日 | P3: 早期予約提案 | Q3: フォローコール | R3: 備考(お客様の声) | S3: 入金経路 | T3: 入金額照合 | U3: ＯＨ打診 | V3: 本舗ロイ区分 | W3: お客様周辺/環境情報 | X3: カウント用
A4: ="▼自動集計" | B4: =COUNTIFS($B$5:$B$504,"One Hitter") | C4: =IFERROR(SUMPRODUCT(($C$5:$C$504<>"")*($D$5:$D$504<>"")*($D$5:$D$504-$C$5:$C$504))/SUMPRODUCT(($C$5:$C$504<>"")*($D$5:$D$504<>"")),0) | D4: =COUNTIFS($B$5:$B$504,"本舗") | E4: =COUNTA($D$5:$D$504) | F4: =IFERROR(SUM($L$5:$L$504)/COUNTA($D$5:$D$504),0) | G4: =COUNTA($G$5:$G$504) | H4: =IFERROR(SUMIFS($L$5:$L$504,$B$5:$B$504,"One Hitter")/COUNTIFS($B$5:$B$504,"One Hitter"),0) | I4: =IFERROR(SUMIFS($L$5:$L$504,$B$5:$B$504,"本舗")/COUNTIFS($B$5:$B$504,"本舗"),0) | J4: =SUMIFS($L$5:$L$504,$B$5:$B$504,"One Hitter") | K4: =SUMIFS($L$5:$L$504,$B$5:$B$504,"本舗") | L4: =SUM($L$5:$L$504) | R4: =COUNTIFS($E$5:$E$504,"HP")+COUNTIFS($E$5:$E$504,"LP")+COUNTIFS($E$5:$E$504,"SNS")+COUNTIFS($E$5:$E$504,"GBP(地図検索)")+COUNTIFS($E$5:$E$504,"公式LINE")+COUNTIFS($E$5:$E$504,"アフィリエイト")+COUNTIFS($E$5:$E$504,"LINE/SMS再販")+COUNTIFS($E$5:$E$504,"SMS")+COUNTIFS($E$5:$E$504,"広告") | S4: =SUMIFS($L$5:$L$504,$E$5:$E$504,"HP")+SUMIFS($L$5:$L$504,$E$5:$E$504,"LP")+SUMIFS($L$5:$L$504,$E$5:$E$504,"SNS")+SUMIFS($L$5:$L$504,$E$5:$E$504,"GBP(地図検索)")+SUMIFS($L$5:$L$504,$E$5:$E$504,"公式LINE")+SUMIFS($L$5:$L$504,$E$5:$E$504,"アフィリエイト")+SUMIFS($L$5:$L$504,$E$5:$E$504,"LINE/SMS再販")+SUMIFS($L$5:$L$504,$E$5:$E$504,"SMS")+SUMIFS($L$5:$L$504,$E$5:$E$504,"広告")

Sheet 9月_売上顧客
A1: ◆ 9月の売上・顧客。入力は 5 行目から。2行目＝今月の目標、4行目＝自動集計（数式・触らない）
A2: 今月目標(売上) | B2: 1800000 | C2: 売上 現在 | D2: =$L$4 | E2: 過不足 | F2: =D2-B2 | G2: 達成率 | H2: =IFERROR(D2/B2,0) | I2: 必要件数 | J2: 46 | K2: 件数 現在 | L2: =$E$4 | M2: 残り件数 | N2: =J2-L2 | O2: ④ネット新規 目標 | P2: 12 | Q2: ④ 現在 | R2: =$R$4
A3: 通し番号 | B3: 売上種類 | C3: 受注日 | D3: 施工日付 | E3: 流入経路 | F3: 流入元の識別子(?src=) | G3: 紹介者（顧客ID） | H3: 氏名 | I3: TEL(-無し) | J3: 郵便番号(-無し) | K3: 住所 | L3: 売上（税込） | M3: 実施メニュー | N3: 施工担当 | O3: フォローコール日 | P3: 早期予約提案 | Q3: フォローコール | R3: 備考(お客様の声) | S3: 入金経路 | T3: 入金額照合 | U3: ＯＨ打診 | V3: 本舗ロイ区分 | W3: お客様周辺/環境情報 | X3: カウント用
A4: ="▼自動集計" | B4: =COUNTIFS($B$5:$B$504,"One Hitter") | C4: =IFERROR(SUMPRODUCT(($C$5:$C$504<>"")*($D$5:$D$504<>"")*($D$5:$D$504-$C$5:$C$504))/SUMPRODUCT(($C$5:$C$504<>"")*($D$5:$D$504<>"")),0) | D4: =COUNTIFS($B$5:$B$504,"本舗") | E4: =COUNTA($D$5:$D$504) | F4: =IFERROR(SUM($L$5:$L$504)/COUNTA($D$5:$D$504),0) | G4: =COUNTA($G$5:$G$504) | H4: =IFERROR(SUMIFS($L$5:$L$504,$B$5:$B$504,"One Hitter")/COUNTIFS($B$5:$B$504,"One Hitter"),0) | I4: =IFERROR(SUMIFS($L$5:$L$504,$B$5:$B$504,"本舗")/COUNTIFS($B$5:$B$504,"本舗"),0) | J4: =SUMIFS($L$5:$L$504,$B$5:$B$504,"One Hitter") | K4: =SUMIFS($L$5:$L$504,$B$5:$B$504,"本舗") | L4: =SUM($L$5:$L$504) | R4: =COUNTIFS($E$5:$E$504,"HP")+COUNTIFS($E$5:$E$504,"LP")+COUNTIFS($E$5:$E$504,"SNS")+COUNTIFS($E$5:$E$504,"GBP(地図検索)")+COUNTIFS($E$5:$E$504,"公式LINE")+COUNTIFS($E$5:$E$504,"アフィリエイト")+COUNTIFS($E$5:$E$504,"LINE/SMS再販")+COUNTIFS($E$5:$E$504,"SMS")+COUNTIFS($E$5:$E$504,"広告") | S4: =SUMIFS($L$5:$L$504,$E$5:$E$504,"HP")+SUMIFS($L$5:$L$504,$E$5:$E$504,"LP")+SUMIFS($L$5:$L$504,$E$5:$E$504,"SNS")+SUMIFS($L$5:$L$504,$E$5:$E$504,"GBP(地図検索)")+SUMIFS($L$5:$L$504,$E$5:$E$504,"公式LINE")+SUMIFS($L$5:$L$504,$E$5:$E$504,"アフィリエイト")+SUMIFS($L$5:$L$504,$E$5:$E$504,"LINE/SMS再販")+SUMIFS($L$5:$L$504,$E$5:$E$504,"SMS")+SUMIFS($L$5:$L$504,$E$5:$E$504,"広告")

Sheet 10月_売上顧客
A1: ◆ 10月の売上・顧客。入力は 5 行目から。2行目＝今月の目標、4行目＝自動集計（数式・触らない）
A2: 今月目標(売上) | B2: 2320000 | C2: 売上 現在 | D2: =$L$4 | E2: 過不足 | F2: =D2-B2 | G2: 達成率 | H2: =IFERROR(D2/B2,0) | I2: 必要件数 | J2: 60 | K2: 件数 現在 | L2: =$E$4 | M2: 残り件数 | N2: =J2-L2 | O2: ④ネット新規 目標 | P2: 16 | Q2: ④ 現在 | R2: =$R$4
A3: 通し番号 | B3: 売上種類 | C3: 受注日 | D3: 施工日付 | E3: 流入経路 | F3: 流入元の識別子(?src=) | G3: 紹介者（顧客ID） | H3: 氏名 | I3: TEL(-無し) | J3: 郵便番号(-無し) | K3: 住所 | L3: 売上（税込） | M3: 実施メニュー | N3: 施工担当 | O3: フォローコール日 | P3: 早期予約提案 | Q3: フォローコール | R3: 備考(お客様の声) | S3: 入金経路 | T3: 入金額照合 | U3: ＯＨ打診 | V3: 本舗ロイ区分 | W3: お客様周辺/環境情報 | X3: カウント用
A4: ="▼自動集計" | B4: =COUNTIFS($B$5:$B$504,"One Hitter") | C4: =IFERROR(SUMPRODUCT(($C$5:$C$504<>"")*($D$5:$D$504<>"")*($D$5:$D$504-$C$5:$C$504))/SUMPRODUCT(($C$5:$C$504<>"")*($D$5:$D$504<>"")),0) | D4: =COUNTIFS($B$5:$B$504,"本舗") | E4: =COUNTA($D$5:$D$504) | F4: =IFERROR(SUM($L$5:$L$504)/COUNTA($D$5:$D$504),0) | G4: =COUNTA($G$5:$G$504) | H4: =IFERROR(SUMIFS($L$5:$L$504,$B$5:$B$504,"One Hitter")/COUNTIFS($B$5:$B$504,"One Hitter"),0) | I4: =IFERROR(SUMIFS($L$5:$L$504,$B$5:$B$504,"本舗")/COUNTIFS($B$5:$B$504,"本舗"),0) | J4: =SUMIFS($L$5:$L$504,$B$5:$B$504,"One Hitter") | K4: =SUMIFS($L$5:$L$504,$B$5:$B$504,"本舗") | L4: =SUM($L$5:$L$504) | R4: =COUNTIFS($E$5:$E$504,"HP")+COUNTIFS($E$5:$E$504,"LP")+COUNTIFS($E$5:$E$504,"SNS")+COUNTIFS($E$5:$E$504,"GBP(地図検索)")+COUNTIFS($E$5:$E$504,"公式LINE")+COUNTIFS($E$5:$E$504,"アフィリエイト")+COUNTIFS($E$5:$E$504,"LINE/SMS再販")+COUNTIFS($E$5:$E$504,"SMS")+COUNTIFS($E$5:$E$504,"広告") | S4: =SUMIFS($L$5:$L$504,$E$5:$E$504,"HP")+SUMIFS($L$5:$L$504,$E$5:$E$504,"LP")+SUMIFS($L$5:$L$504,$E$5:$E$504,"SNS")+SUMIFS($L$5:$L$504,$E$5:$E$504,"GBP(地図検索)")+SUMIFS($L$5:$L$504,$E$5:$E$504,"公式LINE")+SUMIFS($L$5:$L$504,$E$5:$E$504,"アフィリエイト")+SUMIFS($L$5:$L$504,$E$5:$E$504,"LINE/SMS再販")+SUMIFS($L$5:$L$504,$E$5:$E$504,"SMS")+SUMIFS($L$5:$L$504,$E$5:$E$504,"広告")

Sheet 11月_売上顧客
A1: ◆ 11月の売上・顧客。入力は 5 行目から。2行目＝今月の目標、4行目＝自動集計（数式・触らない）
A2: 今月目標(売上) | B2: 2480000 | C2: 売上 現在 | D2: =$L$4 | E2: 過不足 | F2: =D2-B2 | G2: 達成率 | H2: =IFERROR(D2/B2,0) | I2: 必要件数 | J2: 64 | K2: 件数 現在 | L2: =$E$4 | M2: 残り件数 | N2: =J2-L2 | O2: ④ネット新規 目標 | P2: 18 | Q2: ④ 現在 | R2: =$R$4
A3: 通し番号 | B3: 売上種類 | C3: 受注日 | D3: 施工日付 | E3: 流入経路 | F3: 流入元の識別子(?src=) | G3: 紹介者（顧客ID） | H3: 氏名 | I3: TEL(-無し) | J3: 郵便番号(-無し) | K3: 住所 | L3: 売上（税込） | M3: 実施メニュー | N3: 施工担当 | O3: フォローコール日 | P3: 早期予約提案 | Q3: フォローコール | R3: 備考(お客様の声) | S3: 入金経路 | T3: 入金額照合 | U3: ＯＨ打診 | V3: 本舗ロイ区分 | W3: お客様周辺/環境情報 | X3: カウント用
A4: ="▼自動集計" | B4: =COUNTIFS($B$5:$B$504,"One Hitter") | C4: =IFERROR(SUMPRODUCT(($C$5:$C$504<>"")*($D$5:$D$504<>"")*($D$5:$D$504-$C$5:$C$504))/SUMPRODUCT(($C$5:$C$504<>"")*($D$5:$D$504<>"")),0) | D4: =COUNTIFS($B$5:$B$504,"本舗") | E4: =COUNTA($D$5:$D$504) | F4: =IFERROR(SUM($L$5:$L$504)/COUNTA($D$5:$D$504),0) | G4: =COUNTA($G$5:$G$504) | H4: =IFERROR(SUMIFS($L$5:$L$504,$B$5:$B$504,"One Hitter")/COUNTIFS($B$5:$B$504,"One Hitter"),0) | I4: =IFERROR(SUMIFS($L$5:$L$504,$B$5:$B$504,"本舗")/COUNTIFS($B$5:$B$504,"本舗"),0) | J4: =SUMIFS($L$5:$L$504,$B$5:$B$504,"One Hitter") | K4: =SUMIFS($L$5:$L$504,$B$5:$B$504,"本舗") | L4: =SUM($L$5:$L$504) | R4: =COUNTIFS($E$5:$E$504,"HP")+COUNTIFS($E$5:$E$504,"LP")+COUNTIFS($E$5:$E$504,"SNS")+COUNTIFS($E$5:$E$504,"GBP(地図検索)")+COUNTIFS($E$5:$E$504,"公式LINE")+COUNTIFS($E$5:$E$504,"アフィリエイト")+COUNTIFS($E$5:$E$504,"LINE/SMS再販")+COUNTIFS($E$5:$E$504,"SMS")+COUNTIFS($E$5:$E$504,"広告") | S4: =SUMIFS($L$5:$L$504,$E$5:$E$504,"HP")+SUMIFS($L$5:$L$504,$E$5:$E$504,"LP")+SUMIFS($L$5:$L$504,$E$5:$E$504,"SNS")+SUMIFS($L$5:$L$504,$E$5:$E$504,"GBP(地図検索)")+SUMIFS($L$5:$L$504,$E$5:$E$504,"公式LINE")+SUMIFS($L$5:$L$504,$E$5:$E$504,"アフィリエイト")+SUMIFS($L$5:$L$504,$E$5:$E$504,"LINE/SMS再販")+SUMIFS($L$5:$L$504,$E$5:$E$504,"SMS")+SUMIFS($L$5:$L$504,$E$5:$E$504,"広告")

Sheet 12月_売上顧客
A1: ◆ 12月の売上・顧客。入力は 5 行目から。2行目＝今月の目標、4行目＝自動集計（数式・触らない）
A2: 今月目標(売上) | B2: 1940000 | C2: 売上 現在 | D2: =$L$4 | E2: 過不足 | F2: =D2-B2 | G2: 達成率 | H2: =IFERROR(D2/B2,0) | I2: 必要件数 | J2: 45 | K2: 件数 現在 | L2: =$E$4 | M2: 残り件数 | N2: =J2-L2 | O2: ④ネット新規 目標 | P2: 13 | Q2: ④ 現在 | R2: =$R$4
A3: 通し番号 | B3: 売上種類 | C3: 受注日 | D3: 施工日付 | E3: 流入経路 | F3: 流入元の識別子(?src=) | G3: 紹介者（顧客ID） | H3: 氏名 | I3: TEL(-無し) | J3: 郵便番号(-無し) | K3: 住所 | L3: 売上（税込） | M3: 実施メニュー | N3: 施工担当 | O3: フォローコール日 | P3: 早期予約提案 | Q3: フォローコール | R3: 備考(お客様の声) | S3: 入金経路 | T3: 入金額照合 | U3: ＯＨ打診 | V3: 本舗ロイ区分 | W3: お客様周辺/環境情報 | X3: カウント用
A4: ="▼自動集計" | B4: =COUNTIFS($B$5:$B$504,"One Hitter") | C4: =IFERROR(SUMPRODUCT(($C$5:$C$504<>"")*($D$5:$D$504<>"")*($D$5:$D$504-$C$5:$C$504))/SUMPRODUCT(($C$5:$C$504<>"")*($D$5:$D$504<>"")),0) | D4: =COUNTIFS($B$5:$B$504,"本舗") | E4: =COUNTA($D$5:$D$504) | F4: =IFERROR(SUM($L$5:$L$504)/COUNTA($D$5:$D$504),0) | G4: =COUNTA($G$5:$G$504) | H4: =IFERROR(SUMIFS($L$5:$L$504,$B$5:$B$504,"One Hitter")/COUNTIFS($B$5:$B$504,"One Hitter"),0) | I4: =IFERROR(SUMIFS($L$5:$L$504,$B$5:$B$504,"本舗")/COUNTIFS($B$5:$B$504,"本舗"),0) | J4: =SUMIFS($L$5:$L$504,$B$5:$B$504,"One Hitter") | K4: =SUMIFS($L$5:$L$504,$B$5:$B$504,"本舗") | L4: =SUM($L$5:$L$504) | R4: =COUNTIFS($E$5:$E$504,"HP")+COUNTIFS($E$5:$E$504,"LP")+COUNTIFS($E$5:$E$504,"SNS")+COUNTIFS($E$5:$E$504,"GBP(地図検索)")+COUNTIFS($E$5:$E$504,"公式LINE")+COUNTIFS($E$5:$E$504,"アフィリエイト")+COUNTIFS($E$5:$E$504,"LINE/SMS再販")+COUNTIFS($E$5:$E$504,"SMS")+COUNTIFS($E$5:$E$504,"広告") | S4: =SUMIFS($L$5:$L$504,$E$5:$E$504,"HP")+SUMIFS($L$5:$L$504,$E$5:$E$504,"LP")+SUMIFS($L$5:$L$504,$E$5:$E$504,"SNS")+SUMIFS($L$5:$L$504,$E$5:$E$504,"GBP(地図検索)")+SUMIFS($L$5:$L$504,$E$5:$E$504,"公式LINE")+SUMIFS($L$5:$L$504,$E$5:$E$504,"アフィリエイト")+SUMIFS($L$5:$L$504,$E$5:$E$504,"LINE/SMS再販")+SUMIFS($L$5:$L$504,$E$5:$E$504,"SMS")+SUMIFS($L$5:$L$504,$E$5:$E$504,"広告")

Sheet 1月_支出成績
A1: ◆ 1月の経費入力。3行目から下へ足していってよい。右の月次P/Lは行が動かないので壊れない | M1: ▼ 月次P/L（この位置は固定。左の経費表を何行足してもずれません）
A2: No. | B2: 日付 | C2: 時刻 | D2: 品目 | E2: 科目 | F2: 金額 | G2: 備考 | H2: 現金立替え | M2: 項目 | N2: 金額 | O2: 計算の中身 | Q2: ▼ 科目別 集計
M3: 売上 | N3: ='1月_売上顧客'!$L$4 | O3: 1月_売上顧客 の合計売上 | Q3: 科目 | R3: 金額
M4: エアコン台数(参考) | N4: =COUNTIFS('1月_売上顧客'!$M$5:$M$504,"エアコン(ノーマル)")+COUNTIFS('1月_売上顧客'!$M$5:$M$504,"エアコン(ロボ)")+COUNTIFS('1月_売上顧客'!$M$5:$M$504,"天カセ")+COUNTIFS('1月_売上顧客'!$M$5:$M$504,"業務用エアコン1方向") | O4: エアコン(ノーマル/ロボ)・天カセ・業務用1方向 | Q4: 交通費 | R4: =SUMIFS($F$3:$F$302,$E$3:$E$302,"交通費")
M5: 換気扇台数(参考) | N5: =COUNTIFS('1月_売上顧客'!$M$5:$M$504,"換気扇") | O5: 実施メニュー＝換気扇 | Q5: 保険料 | R5: =SUMIFS($F$3:$F$302,$E$3:$E$302,"保険料")
M6: 浴室台数(参考) | N6: =COUNTIFS('1月_売上顧客'!$M$5:$M$504,"浴室") | O6: 実施メニュー＝浴室 | Q6: 通信費 | R6: =SUMIFS($F$3:$F$302,$E$3:$E$302,"通信費")
M7: 資材費 | N7: =N4*373+N5*176+N6*149 | O7: エアコン373 + 換気扇176 + 浴室149 | Q7: 広告費 | R7: =SUMIFS($F$3:$F$302,$E$3:$E$302,"広告費")
M8: 外注費（協力業者） | N8: =SUMIFS($F$3:$F$302,$E$3:$E$302,"外注費") | O8: 経費表の科目＝外注費。★2027年から原価として独立 | Q8: 耐久品 | R8: =SUMIFS($F$3:$F$302,$E$3:$E$302,"耐久品")
M9: 現場人件費（原価） | N9: =SUMIFS($F$3:$F$302,$E$3:$E$302,"現場人件費(原価)") | O9: 経費表の科目＝現場人件費(原価) | Q9: 備品 | R9: =SUMIFS($F$3:$F$302,$E$3:$E$302,"備品")
M10: 原価合計 | N10: =N7+N8+N9 | O10: 資材費＋外注費＋現場人件費 | Q10: 個別ロイ | R10: =SUMIFS($F$3:$F$302,$E$3:$E$302,"個別ロイ")
M11: 売上総利益 | N11: =N3-N10 | O11: 売上 − 原価合計 | Q11: 現場人件費(原価) | R11: =SUMIFS($F$3:$F$302,$E$3:$E$302,"現場人件費(原価)")
Q12: 固定給(販管費) | R12: =SUMIFS($F$3:$F$302,$E$3:$E$302,"固定給(販管費)")
M13: 経費合計（左の表） | N13: =SUM($F$3:$F$302) | O13: 左の経費入力表の金額合計 | Q13: 外注費 | R13: =SUMIFS($F$3:$F$302,$E$3:$E$302,"外注費")
M14: − 原価へ回した分 | N14: =-(N8+N9) | O14: 外注費・現場人件費は原価で数えたので戻す | Q14: その他(備考へ) | R14: =SUMIFS($F$3:$F$302,$E$3:$E$302,"その他(備考へ)")
M15: − 個別ロイ（下で計上） | N15: =-SUMIFS($F$3:$F$302,$E$3:$E$302,"個別ロイ") | O15: ★二重計上を防ぐため、ここで一度引く | Q15: 合計 | R15: =SUM(R4:R14)
M16: ロイヤリティ 固定分 | N16: =IF($N$3+$N$13=0,0,50050) | O16: ★50,050円。左の経費表には入力しないこと（まだ動いていない月は0）
M17: ロイヤリティ 38%分 | N17: =SUMIFS('1月_売上顧客'!$L$5:$L$504,'1月_売上顧客'!$V$5:$V$504,"38%")*0.38 | O17: 本舗ロイ区分＝38% の売上 × 38%
M18: ロイヤリティ 10%分 | N18: =SUMIFS('1月_売上顧客'!$L$5:$L$504,'1月_売上顧客'!$V$5:$V$504,"10%")*0.1 | O18: 本舗ロイ区分＝10% の売上 × 10%
M19: ロイヤリティ 個別実額 | N19: =SUMIFS($F$3:$F$302,$E$3:$E$302,"個別ロイ") | O19: 経費表の科目＝個別ロイ（toB・楽ラクーン等）
M20: ロイヤリティ 合計 | N20: =N16+N17+N18+N19 | O20: 固定＋38%＋10%＋個別
M21: 販売管理費 | N21: =N13+N14+N15+N20 | O21: 経費合計 − 原価分 − 個別ロイ ＋ ロイヤリティ合計
M22: 営業利益 | N22: =N11-N21 | O22: 売上総利益 − 販売管理費
M23: 融資返済 | N23: =IF($N$3+$N$13=0,0,38059) | O23: 固定 38,059円（まだ動いていない月は0）
M24: 経常利益 | N24: =N22-N23 | O24: 営業利益 − 融資返済
M26: 経常利益率 | N26: =IFERROR(N24/N3,0) | O26: 経常利益 ÷ 売上
M28: ▼ 計画（中立）との比較
M29: 計画 売上 | N29: 1440000
M30: 実績 − 計画（売上） | N30: =N3-N29 | O30: マイナスなら赤
M31: 計画 経常利益 | N31: 231914
M32: 実績 − 計画（経常） | N32: =N24-N31 | O32: マイナスなら赤
M33: 計画 件数 | N33: 37
M34: 実績 件数 | N34: ='1月_売上顧客'!$E$4
M36: 【ロイヤリティはこのP/Lだけで数えます】
M37: ・固定分 50,050円は左の経費表に入力しないこと（2026年版はここが二重計上の疑いだった）
M38: ・個別ロイは左の経費表に科目「個別ロイ」で入力する。P/Lは15行目で引いて19行目で足すので、数えるのは1回だけ
M39: 【人件費は2つに分けます】
M40: ・現場人件費(原価) … 現場に出た分。原価に入る
M41: ・固定給(販管費) … 和真さんの固定給40万＋プール10万、新人の給与。販管費に入る
M42: ・歩合（経常利益×45%）の行は2027年から使いません
M43: 【保険料・通信費は「その他」に入れないこと】
...

Sheet 2月_支出成績
A1: ◆ 2月の経費入力。3行目から下へ足していってよい。右の月次P/Lは行が動かないので壊れない | M1: ▼ 月次P/L（この位置は固定。左の経費表を何行足してもずれません）
A2: No. | B2: 日付 | C2: 時刻 | D2: 品目 | E2: 科目 | F2: 金額 | G2: 備考 | H2: 現金立替え | M2: 項目 | N2: 金額 | O2: 計算の中身 | Q2: ▼ 科目別 集計
M3: 売上 | N3: ='2月_売上顧客'!$L$4 | O3: 2月_売上顧客 の合計売上 | Q3: 科目 | R3: 金額
M4: エアコン台数(参考) | N4: =COUNTIFS('2月_売上顧客'!$M$5:$M$504,"エアコン(ノーマル)")+COUNTIFS('2月_売上顧客'!$M$5:$M$504,"エアコン(ロボ)")+COUNTIFS('2月_売上顧客'!$M$5:$M$504,"天カセ")+COUNTIFS('2月_売上顧客'!$M$5:$M$504,"業務用エアコン1方向") | O4: エアコン(ノーマル/ロボ)・天カセ・業務用1方向 | Q4: 交通費 | R4: =SUMIFS($F$3:$F$302,$E$3:$E$302,"交通費")
M5: 換気扇台数(参考) | N5: =COUNTIFS('2月_売上顧客'!$M$5:$M$504,"換気扇") | O5: 実施メニュー＝換気扇 | Q5: 保険料 | R5: =SUMIFS($F$3:$F$302,$E$3:$E$302,"保険料")
M6: 浴室台数(参考) | N6: =COUNTIFS('2月_売上顧客'!$M$5:$M$504,"浴室") | O6: 実施メニュー＝浴室 | Q6: 通信費 | R6: =SUMIFS($F$3:$F$302,$E$3:$E$302,"通信費")
M7: 資材費 | N7: =N4*373+N5*176+N6*149 | O7: エアコン373 + 換気扇176 + 浴室149 | Q7: 広告費 | R7: =SUMIFS($F$3:$F$302,$E$3:$E$302,"広告費")
M8: 外注費（協力業者） | N8: =SUMIFS($F$3:$F$302,$E$3:$E$302,"外注費") | O8: 経費表の科目＝外注費。★2027年から原価として独立 | Q8: 耐久品 | R8: =SUMIFS($F$3:$F$302,$E$3:$E$302,"耐久品")
M9: 現場人件費（原価） | N9: =SUMIFS($F$3:$F$302,$E$3:$E$302,"現場人件費(原価)") | O9: 経費表の科目＝現場人件費(原価) | Q9: 備品 | R9: =SUMIFS($F$3:$F$302,$E$3:$E$302,"備品")
M10: 原価合計 | N10: =N7+N8+N9 | O10: 資材費＋外注費＋現場人件費 | Q10: 個別ロイ | R10: =SUMIFS($F$3:$F$302,$E$3:$E$302,"個別ロイ")
M11: 売上総利益 | N11: =N3-N10 | O11: 売上 − 原価合計 | Q11: 現場人件費(原価) | R11: =SUMIFS($F$3:$F$302,$E$3:$E$302,"現場人件費(原価)")
Q12: 固定給(販管費) | R12: =SUMIFS($F$3:$F$302,$E$3:$E$302,"固定給(販管費)")
M13: 経費合計（左の表） | N13: =SUM($F$3:$F$302) | O13: 左の経費入力表の金額合計 | Q13: 外注費 | R13: =SUMIFS($F$3:$F$302,$E$3:$E$302,"外注費")
M14: − 原価へ回した分 | N14: =-(N8+N9) | O14: 外注費・現場人件費は原価で数えたので戻す | Q14: その他(備考へ) | R14: =SUMIFS($F$3:$F$302,$E$3:$E$302,"その他(備考へ)")
M15: − 個別ロイ（下で計上） | N15: =-SUMIFS($F$3:$F$302,$E$3:$E$302,"個別ロイ") | O15: ★二重計上を防ぐため、ここで一度引く | Q15: 合計 | R15: =SUM(R4:R14)
M16: ロイヤリティ 固定分 | N16: =IF($N$3+$N$13=0,0,50050) | O16: ★50,050円。左の経費表には入力しないこと（まだ動いていない月は0）
M17: ロイヤリティ 38%分 | N17: =SUMIFS('2月_売上顧客'!$L$5:$L$504,'2月_売上顧客'!$V$5:$V$504,"38%")*0.38 | O17: 本舗ロイ区分＝38% の売上 × 38%
M18: ロイヤリティ 10%分 | N18: =SUMIFS('2月_売上顧客'!$L$5:$L$504,'2月_売上顧客'!$V$5:$V$504,"10%")*0.1 | O18: 本舗ロイ区分＝10% の売上 × 10%
M19: ロイヤリティ 個別実額 | N19: =SUMIFS($F$3:$F$302,$E$3:$E$302,"個別ロイ") | O19: 経費表の科目＝個別ロイ（toB・楽ラクーン等）
M20: ロイヤリティ 合計 | N20: =N16+N17+N18+N19 | O20: 固定＋38%＋10%＋個別
M21: 販売管理費 | N21: =N13+N14+N15+N20 | O21: 経費合計 − 原価分 − 個別ロイ ＋ ロイヤリティ合計
M22: 営業利益 | N22: =N11-N21 | O22: 売上総利益 − 販売管理費
M23: 融資返済 | N23: =IF($N$3+$N$13=0,0,38059) | O23: 固定 38,059円（まだ動いていない月は0）
M24: 経常利益 | N24: =N22-N23 | O24: 営業利益 − 融資返済
M26: 経常利益率 | N26: =IFERROR(N24/N3,0) | O26: 経常利益 ÷ 売上
M28: ▼ 計画（中立）との比較
M29: 計画 売上 | N29: 1280000
M30: 実績 − 計画（売上） | N30: =N3-N29 | O30: マイナスなら赤
M31: 計画 経常利益 | N31: -6745
M32: 実績 − 計画（経常） | N32: =N24-N31 | O32: マイナスなら赤
M33: 計画 件数 | N33: 32
M34: 実績 件数 | N34: ='2月_売上顧客'!$E$4
M36: 【ロイヤリティはこのP/Lだけで数えます】
M37: ・固定分 50,050円は左の経費表に入力しないこと（2026年版はここが二重計上の疑いだった）
M38: ・個別ロイは左の経費表に科目「個別ロイ」で入力する。P/Lは15行目で引いて19行目で足すので、数えるのは1回だけ
M39: 【人件費は2つに分けます】
M40: ・現場人件費(原価) … 現場に出た分。原価に入る
M41: ・固定給(販管費) … 和真さんの固定給40万＋プール10万、新人の給与。販管費に入る
M42: ・歩合（経常利益×45%）の行は2027年から使いません
M43: 【保険料・通信費は「その他」に入れないこと】
...

Sheet 3月_支出成績
A1: ◆ 3月の経費入力。3行目から下へ足していってよい。右の月次P/Lは行が動かないので壊れない | M1: ▼ 月次P/L（この位置は固定。左の経費表を何行足してもずれません）
A2: No. | B2: 日付 | C2: 時刻 | D2: 品目 | E2: 科目 | F2: 金額 | G2: 備考 | H2: 現金立替え | M2: 項目 | N2: 金額 | O2: 計算の中身 | Q2: ▼ 科目別 集計
M3: 売上 | N3: ='3月_売上顧客'!$L$4 | O3: 3月_売上顧客 の合計売上 | Q3: 科目 | R3: 金額
M4: エアコン台数(参考) | N4: =COUNTIFS('3月_売上顧客'!$M$5:$M$504,"エアコン(ノーマル)")+COUNTIFS('3月_売上顧客'!$M$5:$M$504,"エアコン(ロボ)")+COUNTIFS('3月_売上顧客'!$M$5:$M$504,"天カセ")+COUNTIFS('3月_売上顧客'!$M$5:$M$504,"業務用エアコン1方向") | O4: エアコン(ノーマル/ロボ)・天カセ・業務用1方向 | Q4: 交通費 | R4: =SUMIFS($F$3:$F$302,$E$3:$E$302,"交通費")
M5: 換気扇台数(参考) | N5: =COUNTIFS('3月_売上顧客'!$M$5:$M$504,"換気扇") | O5: 実施メニュー＝換気扇 | Q5: 保険料 | R5: =SUMIFS($F$3:$F$302,$E$3:$E$302,"保険料")
M6: 浴室台数(参考) | N6: =COUNTIFS('3月_売上顧客'!$M$5:$M$504,"浴室") | O6: 実施メニュー＝浴室 | Q6: 通信費 | R6: =SUMIFS($F$3:$F$302,$E$3:$E$302,"通信費")
M7: 資材費 | N7: =N4*373+N5*176+N6*149 | O7: エアコン373 + 換気扇176 + 浴室149 | Q7: 広告費 | R7: =SUMIFS($F$3:$F$302,$E$3:$E$302,"広告費")
M8: 外注費（協力業者） | N8: =SUMIFS($F$3:$F$302,$E$3:$E$302,"外注費") | O8: 経費表の科目＝外注費。★2027年から原価として独立 | Q8: 耐久品 | R8: =SUMIFS($F$3:$F$302,$E$3:$E$302,"耐久品")
M9: 現場人件費（原価） | N9: =SUMIFS($F$3:$F$302,$E$3:$E$302,"現場人件費(原価)") | O9: 経費表の科目＝現場人件費(原価) | Q9: 備品 | R9: =SUMIFS($F$3:$F$302,$E$3:$E$302,"備品")
M10: 原価合計 | N10: =N7+N8+N9 | O10: 資材費＋外注費＋現場人件費 | Q10: 個別ロイ | R10: =SUMIFS($F$3:$F$302,$E$3:$E$302,"個別ロイ")
M11: 売上総利益 | N11: =N3-N10 | O11: 売上 − 原価合計 | Q11: 現場人件費(原価) | R11: =SUMIFS($F$3:$F$302,$E$3:$E$302,"現場人件費(原価)")
Q12: 固定給(販管費) | R12: =SUMIFS($F$3:$F$302,$E$3:$E$302,"固定給(販管費)")
M13: 経費合計（左の表） | N13: =SUM($F$3:$F$302) | O13: 左の経費入力表の金額合計 | Q13: 外注費 | R13: =SUMIFS($F$3:$F$302,$E$3:$E$302,"外注費")
M14: − 原価へ回した分 | N14: =-(N8+N9) | O14: 外注費・現場人件費は原価で数えたので戻す | Q14: その他(備考へ) | R14: =SUMIFS($F$3:$F$302,$E$3:$E$302,"その他(備考へ)")
M15: − 個別ロイ（下で計上） | N15: =-SUMIFS($F$3:$F$302,$E$3:$E$302,"個別ロイ") | O15: ★二重計上を防ぐため、ここで一度引く | Q15: 合計 | R15: =SUM(R4:R14)
M16: ロイヤリティ 固定分 | N16: =IF($N$3+$N$13=0,0,50050) | O16: ★50,050円。左の経費表には入力しないこと（まだ動いていない月は0）
M17: ロイヤリティ 38%分 | N17: =SUMIFS('3月_売上顧客'!$L$5:$L$504,'3月_売上顧客'!$V$5:$V$504,"38%")*0.38 | O17: 本舗ロイ区分＝38% の売上 × 38%
M18: ロイヤリティ 10%分 | N18: =SUMIFS('3月_売上顧客'!$L$5:$L$504,'3月_売上顧客'!$V$5:$V$504,"10%")*0.1 | O18: 本舗ロイ区分＝10% の売上 × 10%
M19: ロイヤリティ 個別実額 | N19: =SUMIFS($F$3:$F$302,$E$3:$E$302,"個別ロイ") | O19: 経費表の科目＝個別ロイ（toB・楽ラクーン等）
M20: ロイヤリティ 合計 | N20: =N16+N17+N18+N19 | O20: 固定＋38%＋10%＋個別
M21: 販売管理費 | N21: =N13+N14+N15+N20 | O21: 経費合計 − 原価分 − 個別ロイ ＋ ロイヤリティ合計
M22: 営業利益 | N22: =N11-N21 | O22: 売上総利益 − 販売管理費
M23: 融資返済 | N23: =IF($N$3+$N$13=0,0,38059) | O23: 固定 38,059円（まだ動いていない月は0）
M24: 経常利益 | N24: =N22-N23 | O24: 営業利益 − 融資返済
M26: 経常利益率 | N26: =IFERROR(N24/N3,0) | O26: 経常利益 ÷ 売上
M28: ▼ 計画（中立）との比較
M29: 計画 売上 | N29: 1850000
M30: 実績 − 計画（売上） | N30: =N3-N29 | O30: マイナスなら赤
M31: 計画 経常利益 | N31: 303086
M32: 実績 − 計画（経常） | N32: =N24-N31 | O32: マイナスなら赤
M33: 計画 件数 | N33: 46
M34: 実績 件数 | N34: ='3月_売上顧客'!$E$4
M36: 【ロイヤリティはこのP/Lだけで数えます】
M37: ・固定分 50,050円は左の経費表に入力しないこと（2026年版はここが二重計上の疑いだった）
M38: ・個別ロイは左の経費表に科目「個別ロイ」で入力する。P/Lは15行目で引いて19行目で足すので、数えるのは1回だけ
M39: 【人件費は2つに分けます】
M40: ・現場人件費(原価) … 現場に出た分。原価に入る
M41: ・固定給(販管費) … 和真さんの固定給40万＋プール10万、新人の給与。販管費に入る
M42: ・歩合（経常利益×45%）の行は2027年から使いません
M43: 【保険料・通信費は「その他」に入れないこと】
...

Sheet 4月_支出成績
A1: ◆ 4月の経費入力。3行目から下へ足していってよい。右の月次P/Lは行が動かないので壊れない | M1: ▼ 月次P/L（この位置は固定。左の経費表を何行足してもずれません）
A2: No. | B2: 日付 | C2: 時刻 | D2: 品目 | E2: 科目 | F2: 金額 | G2: 備考 | H2: 現金立替え | M2: 項目 | N2: 金額 | O2: 計算の中身 | Q2: ▼ 科目別 集計
M3: 売上 | N3: ='4月_売上顧客'!$L$4 | O3: 4月_売上顧客 の合計売上 | Q3: 科目 | R3: 金額
M4: エアコン台数(参考) | N4: =COUNTIFS('4月_売上顧客'!$M$5:$M$504,"エアコン(ノーマル)")+COUNTIFS('4月_売上顧客'!$M$5:$M$504,"エアコン(ロボ)")+COUNTIFS('4月_売上顧客'!$M$5:$M$504,"天カセ")+COUNTIFS('4月_売上顧客'!$M$5:$M$504,"業務用エアコン1方向") | O4: エアコン(ノーマル/ロボ)・天カセ・業務用1方向 | Q4: 交通費 | R4: =SUMIFS($F$3:$F$302,$E$3:$E$302,"交通費")
M5: 換気扇台数(参考) | N5: =COUNTIFS('4月_売上顧客'!$M$5:$M$504,"換気扇") | O5: 実施メニュー＝換気扇 | Q5: 保険料 | R5: =SUMIFS($F$3:$F$302,$E$3:$E$302,"保険料")
M6: 浴室台数(参考) | N6: =COUNTIFS('4月_売上顧客'!$M$5:$M$504,"浴室") | O6: 実施メニュー＝浴室 | Q6: 通信費 | R6: =SUMIFS($F$3:$F$302,$E$3:$E$302,"通信費")
M7: 資材費 | N7: =N4*373+N5*176+N6*149 | O7: エアコン373 + 換気扇176 + 浴室149 | Q7: 広告費 | R7: =SUMIFS($F$3:$F$302,$E$3:$E$302,"広告費")
M8: 外注費（協力業者） | N8: =SUMIFS($F$3:$F$302,$E$3:$E$302,"外注費") | O8: 経費表の科目＝外注費。★2027年から原価として独立 | Q8: 耐久品 | R8: =SUMIFS($F$3:$F$302,$E$3:$E$302,"耐久品")
M9: 現場人件費（原価） | N9: =SUMIFS($F$3:$F$302,$E$3:$E$302,"現場人件費(原価)") | O9: 経費表の科目＝現場人件費(原価) | Q9: 備品 | R9: =SUMIFS($F$3:$F$302,$E$3:$E$302,"備品")
M10: 原価合計 | N10: =N7+N8+N9 | O10: 資材費＋外注費＋現場人件費 | Q10: 個別ロイ | R10: =SUMIFS($F$3:$F$302,$E$3:$E$302,"個別ロイ")
M11: 売上総利益 | N11: =N3-N10 | O11: 売上 − 原価合計 | Q11: 現場人件費(原価) | R11: =SUMIFS($F$3:$F$302,$E$3:$E$302,"現場人件費(原価)")
Q12: 固定給(販管費) | R12: =SUMIFS($F$3:$F$302,$E$3:$E$302,"固定給(販管費)")
M13: 経費合計（左の表） | N13: =SUM($F$3:$F$302) | O13: 左の経費入力表の金額合計 | Q13: 外注費 | R13: =SUMIFS($F$3:$F$302,$E$3:$E$302,"外注費")
M14: − 原価へ回した分 | N14: =-(N8+N9) | O14: 外注費・現場人件費は原価で数えたので戻す | Q14: その他(備考へ) | R14: =SUMIFS($F$3:$F$302,$E$3:$E$302,"その他(備考へ)")
M15: − 個別ロイ（下で計上） | N15: =-SUMIFS($F$3:$F$302,$E$3:$E$302,"個別ロイ") | O15: ★二重計上を防ぐため、ここで一度引く | Q15: 合計 | R15: =SUM(R4:R14)
M16: ロイヤリティ 固定分 | N16: =IF($N$3+$N$13=0,0,50050) | O16: ★50,050円。左の経費表には入力しないこと（まだ動いていない月は0）
M17: ロイヤリティ 38%分 | N17: =SUMIFS('4月_売上顧客'!$L$5:$L$504,'4月_売上顧客'!$V$5:$V$504,"38%")*0.38 | O17: 本舗ロイ区分＝38% の売上 × 38%
M18: ロイヤリティ 10%分 | N18: =SUMIFS('4月_売上顧客'!$L$5:$L$504,'4月_売上顧客'!$V$5:$V$504,"10%")*0.1 | O18: 本舗ロイ区分＝10% の売上 × 10%
M19: ロイヤリティ 個別実額 | N19: =SUMIFS($F$3:$F$302,$E$3:$E$302,"個別ロイ") | O19: 経費表の科目＝個別ロイ（toB・楽ラクーン等）
M20: ロイヤリティ 合計 | N20: =N16+N17+N18+N19 | O20: 固定＋38%＋10%＋個別
M21: 販売管理費 | N21: =N13+N14+N15+N20 | O21: 経費合計 − 原価分 − 個別ロイ ＋ ロイヤリティ合計
M22: 営業利益 | N22: =N11-N21 | O22: 売上総利益 − 販売管理費
M23: 融資返済 | N23: =IF($N$3+$N$13=0,0,38059) | O23: 固定 38,059円（まだ動いていない月は0）
M24: 経常利益 | N24: =N22-N23 | O24: 営業利益 − 融資返済
M26: 経常利益率 | N26: =IFERROR(N24/N3,0) | O26: 経常利益 ÷ 売上
M28: ▼ 計画（中立）との比較
M29: 計画 売上 | N29: 2260000
M30: 実績 − 計画（売上） | N30: =N3-N29 | O30: マイナスなら赤
M31: 計画 経常利益 | N31: 570807
M32: 実績 − 計画（経常） | N32: =N24-N31 | O32: マイナスなら赤
M33: 計画 件数 | N33: 57
M34: 実績 件数 | N34: ='4月_売上顧客'!$E$4
M36: 【ロイヤリティはこのP/Lだけで数えます】
M37: ・固定分 50,050円は左の経費表に入力しないこと（2026年版はここが二重計上の疑いだった）
M38: ・個別ロイは左の経費表に科目「個別ロイ」で入力する。P/Lは15行目で引いて19行目で足すので、数えるのは1回だけ
M39: 【人件費は2つに分けます】
M40: ・現場人件費(原価) … 現場に出た分。原価に入る
M41: ・固定給(販管費) … 和真さんの固定給40万＋プール10万、新人の給与。販管費に入る
M42: ・歩合（経常利益×45%）の行は2027年から使いません
M43: 【保険料・通信費は「その他」に入れないこと】
...

Sheet 5月_支出成績
A1: ◆ 5月の経費入力。3行目から下へ足していってよい。右の月次P/Lは行が動かないので壊れない | M1: ▼ 月次P/L（この位置は固定。左の経費表を何行足してもずれません）
A2: No. | B2: 日付 | C2: 時刻 | D2: 品目 | E2: 科目 | F2: 金額 | G2: 備考 | H2: 現金立替え | M2: 項目 | N2: 金額 | O2: 計算の中身 | Q2: ▼ 科目別 集計
M3: 売上 | N3: ='5月_売上顧客'!$L$4 | O3: 5月_売上顧客 の合計売上 | Q3: 科目 | R3: 金額
M4: エアコン台数(参考) | N4: =COUNTIFS('5月_売上顧客'!$M$5:$M$504,"エアコン(ノーマル)")+COUNTIFS('5月_売上顧客'!$M$5:$M$504,"エアコン(ロボ)")+COUNTIFS('5月_売上顧客'!$M$5:$M$504,"天カセ")+COUNTIFS('5月_売上顧客'!$M$5:$M$504,"業務用エアコン1方向") | O4: エアコン(ノーマル/ロボ)・天カセ・業務用1方向 | Q4: 交通費 | R4: =SUMIFS($F$3:$F$302,$E$3:$E$302,"交通費")
M5: 換気扇台数(参考) | N5: =COUNTIFS('5月_売上顧客'!$M$5:$M$504,"換気扇") | O5: 実施メニュー＝換気扇 | Q5: 保険料 | R5: =SUMIFS($F$3:$F$302,$E$3:$E$302,"保険料")
M6: 浴室台数(参考) | N6: =COUNTIFS('5月_売上顧客'!$M$5:$M$504,"浴室") | O6: 実施メニュー＝浴室 | Q6: 通信費 | R6: =SUMIFS($F$3:$F$302,$E$3:$E$302,"通信費")
M7: 資材費 | N7: =N4*373+N5*176+N6*149 | O7: エアコン373 + 換気扇176 + 浴室149 | Q7: 広告費 | R7: =SUMIFS($F$3:$F$302,$E$3:$E$302,"広告費")
M8: 外注費（協力業者） | N8: =SUMIFS($F$3:$F$302,$E$3:$E$302,"外注費") | O8: 経費表の科目＝外注費。★2027年から原価として独立 | Q8: 耐久品 | R8: =SUMIFS($F$3:$F$302,$E$3:$E$302,"耐久品")
M9: 現場人件費（原価） | N9: =SUMIFS($F$3:$F$302,$E$3:$E$302,"現場人件費(原価)") | O9: 経費表の科目＝現場人件費(原価) | Q9: 備品 | R9: =SUMIFS($F$3:$F$302,$E$3:$E$302,"備品")
M10: 原価合計 | N10: =N7+N8+N9 | O10: 資材費＋外注費＋現場人件費 | Q10: 個別ロイ | R10: =SUMIFS($F$3:$F$302,$E$3:$E$302,"個別ロイ")
M11: 売上総利益 | N11: =N3-N10 | O11: 売上 − 原価合計 | Q11: 現場人件費(原価) | R11: =SUMIFS($F$3:$F$302,$E$3:$E$302,"現場人件費(原価)")
Q12: 固定給(販管費) | R12: =SUMIFS($F$3:$F$302,$E$3:$E$302,"固定給(販管費)")
M13: 経費合計（左の表） | N13: =SUM($F$3:$F$302) | O13: 左の経費入力表の金額合計 | Q13: 外注費 | R13: =SUMIFS($F$3:$F$302,$E$3:$E$302,"外注費")
M14: − 原価へ回した分 | N14: =-(N8+N9) | O14: 外注費・現場人件費は原価で数えたので戻す | Q14: その他(備考へ) | R14: =SUMIFS($F$3:$F$302,$E$3:$E$302,"その他(備考へ)")
M15: − 個別ロイ（下で計上） | N15: =-SUMIFS($F$3:$F$302,$E$3:$E$302,"個別ロイ") | O15: ★二重計上を防ぐため、ここで一度引く | Q15: 合計 | R15: =SUM(R4:R14)
M16: ロイヤリティ 固定分 | N16: =IF($N$3+$N$13=0,0,50050) | O16: ★50,050円。左の経費表には入力しないこと（まだ動いていない月は0）
M17: ロイヤリティ 38%分 | N17: =SUMIFS('5月_売上顧客'!$L$5:$L$504,'5月_売上顧客'!$V$5:$V$504,"38%")*0.38 | O17: 本舗ロイ区分＝38% の売上 × 38%
M18: ロイヤリティ 10%分 | N18: =SUMIFS('5月_売上顧客'!$L$5:$L$504,'5月_売上顧客'!$V$5:$V$504,"10%")*0.1 | O18: 本舗ロイ区分＝10% の売上 × 10%
M19: ロイヤリティ 個別実額 | N19: =SUMIFS($F$3:$F$302,$E$3:$E$302,"個別ロイ") | O19: 経費表の科目＝個別ロイ（toB・楽ラクーン等）
M20: ロイヤリティ 合計 | N20: =N16+N17+N18+N19 | O20: 固定＋38%＋10%＋個別
M21: 販売管理費 | N21: =N13+N14+N15+N20 | O21: 経費合計 − 原価分 − 個別ロイ ＋ ロイヤリティ合計
M22: 営業利益 | N22: =N11-N21 | O22: 売上総利益 − 販売管理費
M23: 融資返済 | N23: =IF($N$3+$N$13=0,0,38059) | O23: 固定 38,059円（まだ動いていない月は0）
M24: 経常利益 | N24: =N22-N23 | O24: 営業利益 − 融資返済
M26: 経常利益率 | N26: =IFERROR(N24/N3,0) | O26: 経常利益 ÷ 売上
M28: ▼ 計画（中立）との比較
M29: 計画 売上 | N29: 2890000
M30: 実績 − 計画（売上） | N30: =N3-N29 | O30: マイナスなら赤
M31: 計画 経常利益 | N31: 892282
M32: 実績 − 計画（経常） | N32: =N24-N31 | O32: マイナスなら赤
M33: 計画 件数 | N33: 70
M34: 実績 件数 | N34: ='5月_売上顧客'!$E$4
M36: 【ロイヤリティはこのP/Lだけで数えます】
M37: ・固定分 50,050円は左の経費表に入力しないこと（2026年版はここが二重計上の疑いだった）
M38: ・個別ロイは左の経費表に科目「個別ロイ」で入力する。P/Lは15行目で引いて19行目で足すので、数えるのは1回だけ
M39: 【人件費は2つに分けます】
M40: ・現場人件費(原価) … 現場に出た分。原価に入る
M41: ・固定給(販管費) … 和真さんの固定給40万＋プール10万、新人の給与。販管費に入る
M42: ・歩合（経常利益×45%）の行は2027年から使いません
M43: 【保険料・通信費は「その他」に入れないこと】
...

Sheet 6月_支出成績
A1: ◆ 6月の経費入力。3行目から下へ足していってよい。右の月次P/Lは行が動かないので壊れない | M1: ▼ 月次P/L（この位置は固定。左の経費表を何行足してもずれません）
A2: No. | B2: 日付 | C2: 時刻 | D2: 品目 | E2: 科目 | F2: 金額 | G2: 備考 | H2: 現金立替え | M2: 項目 | N2: 金額 | O2: 計算の中身 | Q2: ▼ 科目別 集計
M3: 売上 | N3: ='6月_売上顧客'!$L$4 | O3: 6月_売上顧客 の合計売上 | Q3: 科目 | R3: 金額
M4: エアコン台数(参考) | N4: =COUNTIFS('6月_売上顧客'!$M$5:$M$504,"エアコン(ノーマル)")+COUNTIFS('6月_売上顧客'!$M$5:$M$504,"エアコン(ロボ)")+COUNTIFS('6月_売上顧客'!$M$5:$M$504,"天カセ")+COUNTIFS('6月_売上顧客'!$M$5:$M$504,"業務用エアコン1方向") | O4: エアコン(ノーマル/ロボ)・天カセ・業務用1方向 | Q4: 交通費 | R4: =SUMIFS($F$3:$F$302,$E$3:$E$302,"交通費")
M5: 換気扇台数(参考) | N5: =COUNTIFS('6月_売上顧客'!$M$5:$M$504,"換気扇") | O5: 実施メニュー＝換気扇 | Q5: 保険料 | R5: =SUMIFS($F$3:$F$302,$E$3:$E$302,"保険料")
M6: 浴室台数(参考) | N6: =COUNTIFS('6月_売上顧客'!$M$5:$M$504,"浴室") | O6: 実施メニュー＝浴室 | Q6: 通信費 | R6: =SUMIFS($F$3:$F$302,$E$3:$E$302,"通信費")
M7: 資材費 | N7: =N4*373+N5*176+N6*149 | O7: エアコン373 + 換気扇176 + 浴室149 | Q7: 広告費 | R7: =SUMIFS($F$3:$F$302,$E$3:$E$302,"広告費")
M8: 外注費（協力業者） | N8: =SUMIFS($F$3:$F$302,$E$3:$E$302,"外注費") | O8: 経費表の科目＝外注費。★2027年から原価として独立 | Q8: 耐久品 | R8: =SUMIFS($F$3:$F$302,$E$3:$E$302,"耐久品")
M9: 現場人件費（原価） | N9: =SUMIFS($F$3:$F$302,$E$3:$E$302,"現場人件費(原価)") | O9: 経費表の科目＝現場人件費(原価) | Q9: 備品 | R9: =SUMIFS($F$3:$F$302,$E$3:$E$302,"備品")
M10: 原価合計 | N10: =N7+N8+N9 | O10: 資材費＋外注費＋現場人件費 | Q10: 個別ロイ | R10: =SUMIFS($F$3:$F$302,$E$3:$E$302,"個別ロイ")
M11: 売上総利益 | N11: =N3-N10 | O11: 売上 − 原価合計 | Q11: 現場人件費(原価) | R11: =SUMIFS($F$3:$F$302,$E$3:$E$302,"現場人件費(原価)")
Q12: 固定給(販管費) | R12: =SUMIFS($F$3:$F$302,$E$3:$E$302,"固定給(販管費)")
M13: 経費合計（左の表） | N13: =SUM($F$3:$F$302) | O13: 左の経費入力表の金額合計 | Q13: 外注費 | R13: =SUMIFS($F$3:$F$302,$E$3:$E$302,"外注費")
M14: − 原価へ回した分 | N14: =-(N8+N9) | O14: 外注費・現場人件費は原価で数えたので戻す | Q14: その他(備考へ) | R14: =SUMIFS($F$3:$F$302,$E$3:$E$302,"その他(備考へ)")
M15: − 個別ロイ（下で計上） | N15: =-SUMIFS($F$3:$F$302,$E$3:$E$302,"個別ロイ") | O15: ★二重計上を防ぐため、ここで一度引く | Q15: 合計 | R15: =SUM(R4:R14)
M16: ロイヤリティ 固定分 | N16: =IF($N$3+$N$13=0,0,50050) | O16: ★50,050円。左の経費表には入力しないこと（まだ動いていない月は0）
M17: ロイヤリティ 38%分 | N17: =SUMIFS('6月_売上顧客'!$L$5:$L$504,'6月_売上顧客'!$V$5:$V$504,"38%")*0.38 | O17: 本舗ロイ区分＝38% の売上 × 38%
M18: ロイヤリティ 10%分 | N18: =SUMIFS('6月_売上顧客'!$L$5:$L$504,'6月_売上顧客'!$V$5:$V$504,"10%")*0.1 | O18: 本舗ロイ区分＝10% の売上 × 10%
M19: ロイヤリティ 個別実額 | N19: =SUMIFS($F$3:$F$302,$E$3:$E$302,"個別ロイ") | O19: 経費表の科目＝個別ロイ（toB・楽ラクーン等）
M20: ロイヤリティ 合計 | N20: =N16+N17+N18+N19 | O20: 固定＋38%＋10%＋個別
M21: 販売管理費 | N21: =N13+N14+N15+N20 | O21: 経費合計 − 原価分 − 個別ロイ ＋ ロイヤリティ合計
M22: 営業利益 | N22: =N11-N21 | O22: 売上総利益 − 販売管理費
M23: 融資返済 | N23: =IF($N$3+$N$13=0,0,38059) | O23: 固定 38,059円（まだ動いていない月は0）
M24: 経常利益 | N24: =N22-N23 | O24: 営業利益 − 融資返済
M26: 経常利益率 | N26: =IFERROR(N24/N3,0) | O26: 経常利益 ÷ 売上
M28: ▼ 計画（中立）との比較
M29: 計画 売上 | N29: 3400000
M30: 実績 − 計画（売上） | N30: =N3-N29 | O30: マイナスなら赤
M31: 計画 経常利益 | N31: 1231143
M32: 実績 − 計画（経常） | N32: =N24-N31 | O32: マイナスなら赤
M33: 計画 件数 | N33: 82
M34: 実績 件数 | N34: ='6月_売上顧客'!$E$4
M36: 【ロイヤリティはこのP/Lだけで数えます】
M37: ・固定分 50,050円は左の経費表に入力しないこと（2026年版はここが二重計上の疑いだった）
M38: ・個別ロイは左の経費表に科目「個別ロイ」で入力する。P/Lは15行目で引いて19行目で足すので、数えるのは1回だけ
M39: 【人件費は2つに分けます】
M40: ・現場人件費(原価) … 現場に出た分。原価に入る
M41: ・固定給(販管費) … 和真さんの固定給40万＋プール10万、新人の給与。販管費に入る
M42: ・歩合（経常利益×45%）の行は2027年から使いません
M43: 【保険料・通信費は「その他」に入れないこと】
...

Sheet 7月_支出成績
A1: ◆ 7月の経費入力。3行目から下へ足していってよい。右の月次P/Lは行が動かないので壊れない | M1: ▼ 月次P/L（この位置は固定。左の経費表を何行足してもずれません）
A2: No. | B2: 日付 | C2: 時刻 | D2: 品目 | E2: 科目 | F2: 金額 | G2: 備考 | H2: 現金立替え | M2: 項目 | N2: 金額 | O2: 計算の中身 | Q2: ▼ 科目別 集計
M3: 売上 | N3: ='7月_売上顧客'!$L$4 | O3: 7月_売上顧客 の合計売上 | Q3: 科目 | R3: 金額
M4: エアコン台数(参考) | N4: =COUNTIFS('7月_売上顧客'!$M$5:$M$504,"エアコン(ノーマル)")+COUNTIFS('7月_売上顧客'!$M$5:$M$504,"エアコン(ロボ)")+COUNTIFS('7月_売上顧客'!$M$5:$M$504,"天カセ")+COUNTIFS('7月_売上顧客'!$M$5:$M$504,"業務用エアコン1方向") | O4: エアコン(ノーマル/ロボ)・天カセ・業務用1方向 | Q4: 交通費 | R4: =SUMIFS($F$3:$F$302,$E$3:$E$302,"交通費")
M5: 換気扇台数(参考) | N5: =COUNTIFS('7月_売上顧客'!$M$5:$M$504,"換気扇") | O5: 実施メニュー＝換気扇 | Q5: 保険料 | R5: =SUMIFS($F$3:$F$302,$E$3:$E$302,"保険料")
M6: 浴室台数(参考) | N6: =COUNTIFS('7月_売上顧客'!$M$5:$M$504,"浴室") | O6: 実施メニュー＝浴室 | Q6: 通信費 | R6: =SUMIFS($F$3:$F$302,$E$3:$E$302,"通信費")
M7: 資材費 | N7: =N4*373+N5*176+N6*149 | O7: エアコン373 + 換気扇176 + 浴室149 | Q7: 広告費 | R7: =SUMIFS($F$3:$F$302,$E$3:$E$302,"広告費")
M8: 外注費（協力業者） | N8: =SUMIFS($F$3:$F$302,$E$3:$E$302,"外注費") | O8: 経費表の科目＝外注費。★2027年から原価として独立 | Q8: 耐久品 | R8: =SUMIFS($F$3:$F$302,$E$3:$E$302,"耐久品")
M9: 現場人件費（原価） | N9: =SUMIFS($F$3:$F$302,$E$3:$E$302,"現場人件費(原価)") | O9: 経費表の科目＝現場人件費(原価) | Q9: 備品 | R9: =SUMIFS($F$3:$F$302,$E$3:$E$302,"備品")
M10: 原価合計 | N10: =N7+N8+N9 | O10: 資材費＋外注費＋現場人件費 | Q10: 個別ロイ | R10: =SUMIFS($F$3:$F$302,$E$3:$E$302,"個別ロイ")
M11: 売上総利益 | N11: =N3-N10 | O11: 売上 − 原価合計 | Q11: 現場人件費(原価) | R11: =SUMIFS($F$3:$F$302,$E$3:$E$302,"現場人件費(原価)")
Q12: 固定給(販管費) | R12: =SUMIFS($F$3:$F$302,$E$3:$E$302,"固定給(販管費)")
M13: 経費合計（左の表） | N13: =SUM($F$3:$F$302) | O13: 左の経費入力表の金額合計 | Q13: 外注費 | R13: =SUMIFS($F$3:$F$302,$E$3:$E$302,"外注費")
M14: − 原価へ回した分 | N14: =-(N8+N9) | O14: 外注費・現場人件費は原価で数えたので戻す | Q14: その他(備考へ) | R14: =SUMIFS($F$3:$F$302,$E$3:$E$302,"その他(備考へ)")
M15: − 個別ロイ（下で計上） | N15: =-SUMIFS($F$3:$F$302,$E$3:$E$302,"個別ロイ") | O15: ★二重計上を防ぐため、ここで一度引く | Q15: 合計 | R15: =SUM(R4:R14)
M16: ロイヤリティ 固定分 | N16: =IF($N$3+$N$13=0,0,50050) | O16: ★50,050円。左の経費表には入力しないこと（まだ動いていない月は0）
M17: ロイヤリティ 38%分 | N17: =SUMIFS('7月_売上顧客'!$L$5:$L$504,'7月_売上顧客'!$V$5:$V$504,"38%")*0.38 | O17: 本舗ロイ区分＝38% の売上 × 38%
M18: ロイヤリティ 10%分 | N18: =SUMIFS('7月_売上顧客'!$L$5:$L$504,'7月_売上顧客'!$V$5:$V$504,"10%")*0.1 | O18: 本舗ロイ区分＝10% の売上 × 10%
M19: ロイヤリティ 個別実額 | N19: =SUMIFS($F$3:$F$302,$E$3:$E$302,"個別ロイ") | O19: 経費表の科目＝個別ロイ（toB・楽ラクーン等）
M20: ロイヤリティ 合計 | N20: =N16+N17+N18+N19 | O20: 固定＋38%＋10%＋個別
M21: 販売管理費 | N21: =N13+N14+N15+N20 | O21: 経費合計 − 原価分 − 個別ロイ ＋ ロイヤリティ合計
M22: 営業利益 | N22: =N11-N21 | O22: 売上総利益 − 販売管理費
M23: 融資返済 | N23: =IF($N$3+$N$13=0,0,38059) | O23: 固定 38,059円（まだ動いていない月は0）
M24: 経常利益 | N24: =N22-N23 | O24: 営業利益 − 融資返済
M26: 経常利益率 | N26: =IFERROR(N24/N3,0) | O26: 経常利益 ÷ 売上
M28: ▼ 計画（中立）との比較
M29: 計画 売上 | N29: 2740000
M30: 実績 − 計画（売上） | N30: =N3-N29 | O30: マイナスなら赤
M31: 計画 経常利益 | N31: 813684
M32: 実績 − 計画（経常） | N32: =N24-N31 | O32: マイナスなら赤
M33: 計画 件数 | N33: 68
M34: 実績 件数 | N34: ='7月_売上顧客'!$E$4
M36: 【ロイヤリティはこのP/Lだけで数えます】
M37: ・固定分 50,050円は左の経費表に入力しないこと（2026年版はここが二重計上の疑いだった）
M38: ・個別ロイは左の経費表に科目「個別ロイ」で入力する。P/Lは15行目で引いて19行目で足すので、数えるのは1回だけ
M39: 【人件費は2つに分けます】
M40: ・現場人件費(原価) … 現場に出た分。原価に入る
M41: ・固定給(販管費) … 和真さんの固定給40万＋プール10万、新人の給与。販管費に入る
M42: ・歩合（経常利益×45%）の行は2027年から使いません
M43: 【保険料・通信費は「その他」に入れないこと】
...

Sheet 8月_支出成績
A1: ◆ 8月の経費入力。3行目から下へ足していってよい。右の月次P/Lは行が動かないので壊れない | M1: ▼ 月次P/L（この位置は固定。左の経費表を何行足してもずれません）
A2: No. | B2: 日付 | C2: 時刻 | D2: 品目 | E2: 科目 | F2: 金額 | G2: 備考 | H2: 現金立替え | M2: 項目 | N2: 金額 | O2: 計算の中身 | Q2: ▼ 科目別 集計
M3: 売上 | N3: ='8月_売上顧客'!$L$4 | O3: 8月_売上顧客 の合計売上 | Q3: 科目 | R3: 金額
M4: エアコン台数(参考) | N4: =COUNTIFS('8月_売上顧客'!$M$5:$M$504,"エアコン(ノーマル)")+COUNTIFS('8月_売上顧客'!$M$5:$M$504,"エアコン(ロボ)")+COUNTIFS('8月_売上顧客'!$M$5:$M$504,"天カセ")+COUNTIFS('8月_売上顧客'!$M$5:$M$504,"業務用エアコン1方向") | O4: エアコン(ノーマル/ロボ)・天カセ・業務用1方向 | Q4: 交通費 | R4: =SUMIFS($F$3:$F$302,$E$3:$E$302,"交通費")
M5: 換気扇台数(参考) | N5: =COUNTIFS('8月_売上顧客'!$M$5:$M$504,"換気扇") | O5: 実施メニュー＝換気扇 | Q5: 保険料 | R5: =SUMIFS($F$3:$F$302,$E$3:$E$302,"保険料")
M6: 浴室台数(参考) | N6: =COUNTIFS('8月_売上顧客'!$M$5:$M$504,"浴室") | O6: 実施メニュー＝浴室 | Q6: 通信費 | R6: =SUMIFS($F$3:$F$302,$E$3:$E$302,"通信費")
M7: 資材費 | N7: =N4*373+N5*176+N6*149 | O7: エアコン373 + 換気扇176 + 浴室149 | Q7: 広告費 | R7: =SUMIFS($F$3:$F$302,$E$3:$E$302,"広告費")
M8: 外注費（協力業者） | N8: =SUMIFS($F$3:$F$302,$E$3:$E$302,"外注費") | O8: 経費表の科目＝外注費。★2027年から原価として独立 | Q8: 耐久品 | R8: =SUMIFS($F$3:$F$302,$E$3:$E$302,"耐久品")
M9: 現場人件費（原価） | N9: =SUMIFS($F$3:$F$302,$E$3:$E$302,"現場人件費(原価)") | O9: 経費表の科目＝現場人件費(原価) | Q9: 備品 | R9: =SUMIFS($F$3:$F$302,$E$3:$E$302,"備品")
M10: 原価合計 | N10: =N7+N8+N9 | O10: 資材費＋外注費＋現場人件費 | Q10: 個別ロイ | R10: =SUMIFS($F$3:$F$302,$E$3:$E$302,"個別ロイ")
M11: 売上総利益 | N11: =N3-N10 | O11: 売上 − 原価合計 | Q11: 現場人件費(原価) | R11: =SUMIFS($F$3:$F$302,$E$3:$E$302,"現場人件費(原価)")
Q12: 固定給(販管費) | R12: =SUMIFS($F$3:$F$302,$E$3:$E$302,"固定給(販管費)")
M13: 経費合計（左の表） | N13: =SUM($F$3:$F$302) | O13: 左の経費入力表の金額合計 | Q13: 外注費 | R13: =SUMIFS($F$3:$F$302,$E$3:$E$302,"外注費")
M14: − 原価へ回した分 | N14: =-(N8+N9) | O14: 外注費・現場人件費は原価で数えたので戻す | Q14: その他(備考へ) | R14: =SUMIFS($F$3:$F$302,$E$3:$E$302,"その他(備考へ)")
M15: − 個別ロイ（下で計上） | N15: =-SUMIFS($F$3:$F$302,$E$3:$E$302,"個別ロイ") | O15: ★二重計上を防ぐため、ここで一度引く | Q15: 合計 | R15: =SUM(R4:R14)
M16: ロイヤリティ 固定分 | N16: =IF($N$3+$N$13=0,0,50050) | O16: ★50,050円。左の経費表には入力しないこと（まだ動いていない月は0）
M17: ロイヤリティ 38%分 | N17: =SUMIFS('8月_売上顧客'!$L$5:$L$504,'8月_売上顧客'!$V$5:$V$504,"38%")*0.38 | O17: 本舗ロイ区分＝38% の売上 × 38%
M18: ロイヤリティ 10%分 | N18: =SUMIFS('8月_売上顧客'!$L$5:$L$504,'8月_売上顧客'!$V$5:$V$504,"10%")*0.1 | O18: 本舗ロイ区分＝10% の売上 × 10%
M19: ロイヤリティ 個別実額 | N19: =SUMIFS($F$3:$F$302,$E$3:$E$302,"個別ロイ") | O19: 経費表の科目＝個別ロイ（toB・楽ラクーン等）
M20: ロイヤリティ 合計 | N20: =N16+N17+N18+N19 | O20: 固定＋38%＋10%＋個別
M21: 販売管理費 | N21: =N13+N14+N15+N20 | O21: 経費合計 − 原価分 − 個別ロイ ＋ ロイヤリティ合計
M22: 営業利益 | N22: =N11-N21 | O22: 売上総利益 − 販売管理費
M23: 融資返済 | N23: =IF($N$3+$N$13=0,0,38059) | O23: 固定 38,059円（まだ動いていない月は0）
M24: 経常利益 | N24: =N22-N23 | O24: 営業利益 − 融資返済
M26: 経常利益率 | N26: =IFERROR(N24/N3,0) | O26: 経常利益 ÷ 売上
M28: ▼ 計画（中立）との比較
M29: 計画 売上 | N29: 1600000
M30: 実績 − 計画（売上） | N30: =N3-N29 | O30: マイナスなら赤
M31: 計画 経常利益 | N31: 115573
M32: 実績 − 計画（経常） | N32: =N24-N31 | O32: マイナスなら赤
M33: 計画 件数 | N33: 42
M34: 実績 件数 | N34: ='8月_売上顧客'!$E$4
M36: 【ロイヤリティはこのP/Lだけで数えます】
M37: ・固定分 50,050円は左の経費表に入力しないこと（2026年版はここが二重計上の疑いだった）
M38: ・個別ロイは左の経費表に科目「個別ロイ」で入力する。P/Lは15行目で引いて19行目で足すので、数えるのは1回だけ
M39: 【人件費は2つに分けます】
M40: ・現場人件費(原価) … 現場に出た分。原価に入る
M41: ・固定給(販管費) … 和真さんの固定給40万＋プール10万、新人の給与。販管費に入る
M42: ・歩合（経常利益×45%）の行は2027年から使いません
M43: 【保険料・通信費は「その他」に入れないこと】
...

Sheet 9月_支出成績
A1: ◆ 9月の経費入力。3行目から下へ足していってよい。右の月次P/Lは行が動かないので壊れない | M1: ▼ 月次P/L（この位置は固定。左の経費表を何行足してもずれません）
A2: No. | B2: 日付 | C2: 時刻 | D2: 品目 | E2: 科目 | F2: 金額 | G2: 備考 | H2: 現金立替え | M2: 項目 | N2: 金額 | O2: 計算の中身 | Q2: ▼ 科目別 集計
M3: 売上 | N3: ='9月_売上顧客'!$L$4 | O3: 9月_売上顧客 の合計売上 | Q3: 科目 | R3: 金額
M4: エアコン台数(参考) | N4: =COUNTIFS('9月_売上顧客'!$M$5:$M$504,"エアコン(ノーマル)")+COUNTIFS('9月_売上顧客'!$M$5:$M$504,"エアコン(ロボ)")+COUNTIFS('9月_売上顧客'!$M$5:$M$504,"天カセ")+COUNTIFS('9月_売上顧客'!$M$5:$M$504,"業務用エアコン1方向") | O4: エアコン(ノーマル/ロボ)・天カセ・業務用1方向 | Q4: 交通費 | R4: =SUMIFS($F$3:$F$302,$E$3:$E$302,"交通費")
M5: 換気扇台数(参考) | N5: =COUNTIFS('9月_売上顧客'!$M$5:$M$504,"換気扇") | O5: 実施メニュー＝換気扇 | Q5: 保険料 | R5: =SUMIFS($F$3:$F$302,$E$3:$E$302,"保険料")
M6: 浴室台数(参考) | N6: =COUNTIFS('9月_売上顧客'!$M$5:$M$504,"浴室") | O6: 実施メニュー＝浴室 | Q6: 通信費 | R6: =SUMIFS($F$3:$F$302,$E$3:$E$302,"通信費")
M7: 資材費 | N7: =N4*373+N5*176+N6*149 | O7: エアコン373 + 換気扇176 + 浴室149 | Q7: 広告費 | R7: =SUMIFS($F$3:$F$302,$E$3:$E$302,"広告費")
M8: 外注費（協力業者） | N8: =SUMIFS($F$3:$F$302,$E$3:$E$302,"外注費") | O8: 経費表の科目＝外注費。★2027年から原価として独立 | Q8: 耐久品 | R8: =SUMIFS($F$3:$F$302,$E$3:$E$302,"耐久品")
M9: 現場人件費（原価） | N9: =SUMIFS($F$3:$F$302,$E$3:$E$302,"現場人件費(原価)") | O9: 経費表の科目＝現場人件費(原価) | Q9: 備品 | R9: =SUMIFS($F$3:$F$302,$E$3:$E$302,"備品")
M10: 原価合計 | N10: =N7+N8+N9 | O10: 資材費＋外注費＋現場人件費 | Q10: 個別ロイ | R10: =SUMIFS($F$3:$F$302,$E$3:$E$302,"個別ロイ")
M11: 売上総利益 | N11: =N3-N10 | O11: 売上 − 原価合計 | Q11: 現場人件費(原価) | R11: =SUMIFS($F$3:$F$302,$E$3:$E$302,"現場人件費(原価)")
Q12: 固定給(販管費) | R12: =SUMIFS($F$3:$F$302,$E$3:$E$302,"固定給(販管費)")
M13: 経費合計（左の表） | N13: =SUM($F$3:$F$302) | O13: 左の経費入力表の金額合計 | Q13: 外注費 | R13: =SUMIFS($F$3:$F$302,$E$3:$E$302,"外注費")
M14: − 原価へ回した分 | N14: =-(N8+N9) | O14: 外注費・現場人件費は原価で数えたので戻す | Q14: その他(備考へ) | R14: =SUMIFS($F$3:$F$302,$E$3:$E$302,"その他(備考へ)")
M15: − 個別ロイ（下で計上） | N15: =-SUMIFS($F$3:$F$302,$E$3:$E$302,"個別ロイ") | O15: ★二重計上を防ぐため、ここで一度引く | Q15: 合計 | R15: =SUM(R4:R14)
M16: ロイヤリティ 固定分 | N16: =IF($N$3+$N$13=0,0,50050) | O16: ★50,050円。左の経費表には入力しないこと（まだ動いていない月は0）
M17: ロイヤリティ 38%分 | N17: =SUMIFS('9月_売上顧客'!$L$5:$L$504,'9月_売上顧客'!$V$5:$V$504,"38%")*0.38 | O17: 本舗ロイ区分＝38% の売上 × 38%
M18: ロイヤリティ 10%分 | N18: =SUMIFS('9月_売上顧客'!$L$5:$L$504,'9月_売上顧客'!$V$5:$V$504,"10%")*0.1 | O18: 本舗ロイ区分＝10% の売上 × 10%
M19: ロイヤリティ 個別実額 | N19: =SUMIFS($F$3:$F$302,$E$3:$E$302,"個別ロイ") | O19: 経費表の科目＝個別ロイ（toB・楽ラクーン等）
M20: ロイヤリティ 合計 | N20: =N16+N17+N18+N19 | O20: 固定＋38%＋10%＋個別
M21: 販売管理費 | N21: =N13+N14+N15+N20 | O21: 経費合計 − 原価分 − 個別ロイ ＋ ロイヤリティ合計
M22: 営業利益 | N22: =N11-N21 | O22: 売上総利益 − 販売管理費
M23: 融資返済 | N23: =IF($N$3+$N$13=0,0,38059) | O23: 固定 38,059円（まだ動いていない月は0）
M24: 経常利益 | N24: =N22-N23 | O24: 営業利益 − 融資返済
M26: 経常利益率 | N26: =IFERROR(N24/N3,0) | O26: 経常利益 ÷ 売上
M28: ▼ 計画（中立）との比較
M29: 計画 売上 | N29: 1800000
M30: 実績 − 計画（売上） | N30: =N3-N29 | O30: マイナスなら赤
M31: 計画 経常利益 | N31: 231903
M32: 実績 − 計画（経常） | N32: =N24-N31 | O32: マイナスなら赤
M33: 計画 件数 | N33: 46
M34: 実績 件数 | N34: ='9月_売上顧客'!$E$4
M36: 【ロイヤリティはこのP/Lだけで数えます】
M37: ・固定分 50,050円は左の経費表に入力しないこと（2026年版はここが二重計上の疑いだった）
M38: ・個別ロイは左の経費表に科目「個別ロイ」で入力する。P/Lは15行目で引いて19行目で足すので、数えるのは1回だけ
M39: 【人件費は2つに分けます】
M40: ・現場人件費(原価) … 現場に出た分。原価に入る
M41: ・固定給(販管費) … 和真さんの固定給40万＋プール10万、新人の給与。販管費に入る
M42: ・歩合（経常利益×45%）の行は2027年から使いません
M43: 【保険料・通信費は「その他」に入れないこと】
...

Sheet 10月_支出成績
A1: ◆ 10月の経費入力。3行目から下へ足していってよい。右の月次P/Lは行が動かないので壊れない | M1: ▼ 月次P/L（この位置は固定。左の経費表を何行足してもずれません）
A2: No. | B2: 日付 | C2: 時刻 | D2: 品目 | E2: 科目 | F2: 金額 | G2: 備考 | H2: 現金立替え | M2: 項目 | N2: 金額 | O2: 計算の中身 | Q2: ▼ 科目別 集計
M3: 売上 | N3: ='10月_売上顧客'!$L$4 | O3: 10月_売上顧客 の合計売上 | Q3: 科目 | R3: 金額
M4: エアコン台数(参考) | N4: =COUNTIFS('10月_売上顧客'!$M$5:$M$504,"エアコン(ノーマル)")+COUNTIFS('10月_売上顧客'!$M$5:$M$504,"エアコン(ロボ)")+COUNTIFS('10月_売上顧客'!$M$5:$M$504,"天カセ")+COUNTIFS('10月_売上顧客'!$M$5:$M$504,"業務用エアコン1方向") | O4: エアコン(ノーマル/ロボ)・天カセ・業務用1方向 | Q4: 交通費 | R4: =SUMIFS($F$3:$F$302,$E$3:$E$302,"交通費")
M5: 換気扇台数(参考) | N5: =COUNTIFS('10月_売上顧客'!$M$5:$M$504,"換気扇") | O5: 実施メニュー＝換気扇 | Q5: 保険料 | R5: =SUMIFS($F$3:$F$302,$E$3:$E$302,"保険料")
M6: 浴室台数(参考) | N6: =COUNTIFS('10月_売上顧客'!$M$5:$M$504,"浴室") | O6: 実施メニュー＝浴室 | Q6: 通信費 | R6: =SUMIFS($F$3:$F$302,$E$3:$E$302,"通信費")
M7: 資材費 | N7: =N4*373+N5*176+N6*149 | O7: エアコン373 + 換気扇176 + 浴室149 | Q7: 広告費 | R7: =SUMIFS($F$3:$F$302,$E$3:$E$302,"広告費")
M8: 外注費（協力業者） | N8: =SUMIFS($F$3:$F$302,$E$3:$E$302,"外注費") | O8: 経費表の科目＝外注費。★2027年から原価として独立 | Q8: 耐久品 | R8: =SUMIFS($F$3:$F$302,$E$3:$E$302,"耐久品")
M9: 現場人件費（原価） | N9: =SUMIFS($F$3:$F$302,$E$3:$E$302,"現場人件費(原価)") | O9: 経費表の科目＝現場人件費(原価) | Q9: 備品 | R9: =SUMIFS($F$3:$F$302,$E$3:$E$302,"備品")
M10: 原価合計 | N10: =N7+N8+N9 | O10: 資材費＋外注費＋現場人件費 | Q10: 個別ロイ | R10: =SUMIFS($F$3:$F$302,$E$3:$E$302,"個別ロイ")
M11: 売上総利益 | N11: =N3-N10 | O11: 売上 − 原価合計 | Q11: 現場人件費(原価) | R11: =SUMIFS($F$3:$F$302,$E$3:$E$302,"現場人件費(原価)")
Q12: 固定給(販管費) | R12: =SUMIFS($F$3:$F$302,$E$3:$E$302,"固定給(販管費)")
M13: 経費合計（左の表） | N13: =SUM($F$3:$F$302) | O13: 左の経費入力表の金額合計 | Q13: 外注費 | R13: =SUMIFS($F$3:$F$302,$E$3:$E$302,"外注費")
M14: − 原価へ回した分 | N14: =-(N8+N9) | O14: 外注費・現場人件費は原価で数えたので戻す | Q14: その他(備考へ) | R14: =SUMIFS($F$3:$F$302,$E$3:$E$302,"その他(備考へ)")
M15: − 個別ロイ（下で計上） | N15: =-SUMIFS($F$3:$F$302,$E$3:$E$302,"個別ロイ") | O15: ★二重計上を防ぐため、ここで一度引く | Q15: 合計 | R15: =SUM(R4:R14)
M16: ロイヤリティ 固定分 | N16: =IF($N$3+$N$13=0,0,50050) | O16: ★50,050円。左の経費表には入力しないこと（まだ動いていない月は0）
M17: ロイヤリティ 38%分 | N17: =SUMIFS('10月_売上顧客'!$L$5:$L$504,'10月_売上顧客'!$V$5:$V$504,"38%")*0.38 | O17: 本舗ロイ区分＝38% の売上 × 38%
M18: ロイヤリティ 10%分 | N18: =SUMIFS('10月_売上顧客'!$L$5:$L$504,'10月_売上顧客'!$V$5:$V$504,"10%")*0.1 | O18: 本舗ロイ区分＝10% の売上 × 10%
M19: ロイヤリティ 個別実額 | N19: =SUMIFS($F$3:$F$302,$E$3:$E$302,"個別ロイ") | O19: 経費表の科目＝個別ロイ（toB・楽ラクーン等）
M20: ロイヤリティ 合計 | N20: =N16+N17+N18+N19 | O20: 固定＋38%＋10%＋個別
M21: 販売管理費 | N21: =N13+N14+N15+N20 | O21: 経費合計 − 原価分 − 個別ロイ ＋ ロイヤリティ合計
M22: 営業利益 | N22: =N11-N21 | O22: 売上総利益 − 販売管理費
M23: 融資返済 | N23: =IF($N$3+$N$13=0,0,38059) | O23: 固定 38,059円（まだ動いていない月は0）
M24: 経常利益 | N24: =N22-N23 | O24: 営業利益 − 融資返済
M26: 経常利益率 | N26: =IFERROR(N24/N3,0) | O26: 経常利益 ÷ 売上
M28: ▼ 計画（中立）との比較
M29: 計画 売上 | N29: 2320000
M30: 実績 − 計画（売上） | N30: =N3-N29 | O30: マイナスなら赤
M31: 計画 経常利益 | N31: 503051
M32: 実績 − 計画（経常） | N32: =N24-N31 | O32: マイナスなら赤
M33: 計画 件数 | N33: 60
M34: 実績 件数 | N34: ='10月_売上顧客'!$E$4
M36: 【ロイヤリティはこのP/Lだけで数えます】
M37: ・固定分 50,050円は左の経費表に入力しないこと（2026年版はここが二重計上の疑いだった）
M38: ・個別ロイは左の経費表に科目「個別ロイ」で入力する。P/Lは15行目で引いて19行目で足すので、数えるのは1回だけ
M39: 【人件費は2つに分けます】
M40: ・現場人件費(原価) … 現場に出た分。原価に入る
M41: ・固定給(販管費) … 和真さんの固定給40万＋プール10万、新人の給与。販管費に入る
M42: ・歩合（経常利益×45%）の行は2027年から使いません
M43: 【保険料・通信費は「その他」に入れないこと】
...

Sheet 11月_支出成績
A1: ◆ 11月の経費入力。3行目から下へ足していってよい。右の月次P/Lは行が動かないので壊れない | M1: ▼ 月次P/L（この位置は固定。左の経費表を何行足してもずれません）
A2: No. | B2: 日付 | C2: 時刻 | D2: 品目 | E2: 科目 | F2: 金額 | G2: 備考 | H2: 現金立替え | M2: 項目 | N2: 金額 | O2: 計算の中身 | Q2: ▼ 科目別 集計
M3: 売上 | N3: ='11月_売上顧客'!$L$4 | O3: 11月_売上顧客 の合計売上 | Q3: 科目 | R3: 金額
